Workbook

Sheet Sprint N°1
A1: ="Control del Sprint N°1 – "&Resumen_Sprints!B6 -> Control del Sprint N°1 – Fase Análisis y Planificación
A3: Historias de Usuario o Spike | B3: horas estimadas | C3: DIA | J3: Total
C4: 1 | D4: 2 | E4: 3 | F4: 4 | G4: 5 | H4: 6 | I4: 7
A5: Fase Análisis y Planificación | B5: =SUM(B6:B10) -> 43
A6: Kick Off | B6: 8 | C6: 7 | D6: 1 | J6: =SUM(C6:I6) -> 8
A7: Documento de Visión y Roles Scrum | B7: 8 | D7: 5 | E7: 3 | J7: =SUM(C7:I7) -> 8
A8: Aprobación de la Visión con Patrocinadores | B8: 1 | E8: 3 | J8: =SUM(C8:I8) -> 3
A9: Definición de Requerimientos Generales (Product Backlog inicial) | B9: 18 | E9: 1 | F9: 5 | G9: 7 | H9: 3 | J9: =SUM(C9:I9) -> 16
A10: Organización del Equipo y Herramientas (repositorio, tablero) | B10: 8 | H10: 3 | I10: 5 | J10: =SUM(C10:I10) -> 8
A13: Día (0 = inicio del sprint) | B13: 0 | C13: =C$4 -> 1 | D13: =D$4 -> 2 | E13: =E$4 -> 3 | F13: =F$4 -> 4 | G13: =G$4 -> 5 | H13: =H$4 -> 6 | I13: =I$4 -> 7
A14: Reales de producto por realizar | B14: =SUM(B6:B10) -> 43 | C14: =B14-SUM(C6:C10) -> 36 | D14: =C14-SUM(D6:D10) -> 30 | E14: =D14-SUM(E6:E10) -> 23 | F14: =E14-SUM(F6:F10) -> 18 | G14: =F14-SUM(G6:G10) -> 11 | H14: =G14-SUM(H6:H10) -> 5 | I14: =H14-SUM(I6:I10) -> 0
A16: Estimadas de producto por realizar | B16: =SUM(B6:B10) -> 43 | C16: =$B$16*(1-C$4/COUNT($C$4:$I$4)) -> 36.857143 | D16: =$B$16*(1-D$4/COUNT($C$4:$I$4)) -> 30.714286 | E16: =$B$16*(1-E$4/COUNT($C$4:$I$4)) -> 24.571429 | F16: =$B$16*(1-F$4/COUNT($C$4:$I$4)) -> 18.428571 | G16: =$B$16*(1-G$4/COUNT($C$4:$I$4)) -> 12.285714 | H16: =$B$16*(1-H$4/COUNT($C$4:$I$4)) -> 6.1428571 | I16: =$B$16*(1-I$4/COUNT($C$4:$I$4)) -> 0

Sheet Sprint N°2
A1: ="Control del Sprint N°2 – "&Resumen_Sprints!B7 -> Control del Sprint N°2 – Fase Diseño
A3: Historias de Usuario o Spike | B3: horas estimadas | C3: DIA | P3: Total
C4: 1 | D4: 2 | E4: 3 | F4: 4 | G4: 5 | H4: 6 | I4: 7 | J4: 8 | K4: 9 | L4: 10 | M4: 11 | N4: 12 | O4: 13
A5: Fase Diseño | B5: =SUM(B6:B11) -> 98
A6: Captura de Requerimientos Específicos (Historias de Usuario) | B6: 16 | C6: 7 | D6: 6 | E6: 3 | P6: =SUM(C6:O6) -> 16
A7: Análisis de Requerimientos y Criterios de Aceptación | B7: 14 | E7: 4 | F7: 7 | G7: 3 | P7: =SUM(C7:O7) -> 14
A8: Diseño de la Solución. Modelo de Datos y UML | B8: 23 | G8: 7 | H8: 6 | I8: 7 | J8: 2 | P8: =SUM(C8:O8) -> 22
A9: Diseño de Prototipos de Interfaz | B9: 18 | J9: 6 | K9: 10 | L9: 2 | P9: =SUM(C9:O9) -> 18
A10: Diseño del Algoritmo de Cubicación | B10: 11 | L10: 6 | M10: 6 | P10: =SUM(C10:O10) -> 12
A11: Plan de Proyecto y Product Backlog Priorizado | B11: 16 | M11: 1 | N11: 10 | O11: 5 | P11: =SUM(C11:O11) -> 16
A14: Día (0 = inicio del sprint) | B14: 0 | C14: =C$4 -> 1 | D14: =D$4 -> 2 | E14: =E$4 -> 3 | F14: =F$4 -> 4 | G14: =G$4 -> 5 | H14: =H$4 -> 6 | I14: =I$4 -> 7 | J14: =J$4 -> 8 | ... O14: =O$4 -> 13
A15: Reales de producto por realizar | B15: =SUM(B6:B11) -> 98 | C15: =B15-SUM(C6:C11) -> 91 | D15: =C15-SUM(D6:D11) -> 85 | E15: =D15-SUM(E6:E11) -> 78 | F15: =E15-SUM(F6:F11) -> 71 | G15: =F15-SUM(G6:G11) -> 61 | H15: =G15-SUM(H6:H11) -> 55 | I15: =H15-SUM(I6:I11) -> 48 | J15: =I15-SUM(J6:J11) -> 40 | ... O15: =N15-SUM(O6:O11) -> 0
A17: Estimadas de producto por realizar | B17: =SUM(B6:B11) -> 98 | C17: =$B$17*(1-C$4/COUNT($C$4:$O$4)) -> 90.461538 | D17: =$B$17*(1-D$4/COUNT($C$4:$O$4)) -> 82.923077 | E17: =$B$17*(1-E$4/COUNT($C$4:$O$4)) -> 75.384615 | F17: =$B$17*(1-F$4/COUNT($C$4:$O$4)) -> 67.846154 | G17: =$B$17*(1-G$4/COUNT($C$4:$O$4)) -> 60.307692 | H17: =$B$17*(1-H$4/COUNT($C$4:$O$4)) -> 52.769231 | I17: =$B$17*(1-I$4/COUNT($C$4:$O$4)) -> 45.230769 | J17: =$B$17*(1-J$4/COUNT($C$4:$O$4)) -> 37.692308 | ... O17: =$B$17*(1-O$4/COUNT($C$4:$O$4)) -> 0

Sheet Sprint N°3
A1: ="Control del Sprint N°3 – "&Resumen_Sprints!B8 -> Control del Sprint N°3 – Base de Datos y Catálogo de Materiales
A3: Historias de Usuario o Spike | B3: horas estimadas | C3: DIA | J3: Total
C4: 1 | D4: 2 | E4: 3 | F4: 4 | G4: 5 | H4: 6 | I4: 7
A5: Base de Datos y Catálogo de Materiales | B5: =SUM(B6:B9) -> 47
A6: Coordinación del Objetivos Sprint 3 | B6: 1 | C6: 1 | J6: =SUM(C6:I6) -> 1
A7: Implementación del Ambiente de Desarrollo | B7: 10 | C7: 5 | D7: 5 | J7: =SUM(C7:I7) -> 10
A8: Modelo Relacional de Base de Datos | B8: 19 | E8: 7 | F8: 8 | G8: 4 | J8: =SUM(C8:I8) -> 19
A9: Catálogo de Materiales y Poblamiento Inicial | B9: 17 | G9: 2 | H9: 8 | I9: 7 | J9: =SUM(C9:I9) -> 17
A12: Día (0 = inicio del sprint) | B12: 0 | C12: =C$4 -> 1 | D12: =D$4 -> 2 | E12: =E$4 -> 3 | F12: =F$4 -> 4 | G12: =G$4 -> 5 | H12: =H$4 -> 6 | I12: =I$4 -> 7
A13: Reales de producto por realizar | B13: =SUM(B6:B9) -> 47 | C13: =B13-SUM(C6:C9) -> 41 | D13: =C13-SUM(D6:D9) -> 36 | E13: =D13-SUM(E6:E9) -> 29 | F13: =E13-SUM(F6:F9) -> 21 | G13: =F13-SUM(G6:G9) -> 15 | H13: =G13-SUM(H6:H9) -> 7 | I13: =H13-SUM(I6:I9) -> 0
A15: Estimadas de producto por realizar | B15: =SUM(B6:B9) -> 47 | C15: =$B$15*(1-C$4/COUNT($C$4:$I$4)) -> 40.285714 | D15: =$B$15*(1-D$4/COUNT($C$4:$I$4)) -> 33.571429 | E15: =$B$15*(1-E$4/COUNT($C$4:$I$4)) -> 26.857143 | F15: =$B$15*(1-F$4/COUNT($C$4:$I$4)) -> 20.142857 | G15: =$B$15*(1-G$4/COUNT($C$4:$I$4)) -> 13.428571 | H15: =$B$15*(1-H$4/COUNT($C$4:$I$4)) -> 6.7142857 | I15: =$B$15*(1-I$4/COUNT($C$4:$I$4)) -> 0

Sheet Sprint N°4
A1: ="Control del Sprint N°4 – "&Resumen_Sprints!B9 -> Control del Sprint N°4 – Motor de Simulación y Algoritmo de Cálculo
A3: Historias de Usuario o Spike | B3: horas estimadas | C3: DIA | Q3: Total
C4: 1 | D4: 2 | E4: 3 | F4: 4 | G4: 5 | H4: 6 | I4: 7 | J4: 8 | K4: 9 | L4: 10 | M4: 11 | N4: 12 | O4: 13 | P4: 14
A5: Motor de Simulación y Algoritmo de Cálculo | B5: =SUM(B6:B9) -> 91
A6: Coordinación delObjetivos Sprint 4 | B6: 1 | C6: 1 | Q6: =SUM(C6:P6) -> 1
A7: Algoritmo de Cubicación (cálculo de materiales) | B7: 39 | C7: 4 | D7: 5 | E7: 5 | F7: 7 | G7: 6 | H7: 7 | I7: 4 | Q7: =SUM(C7:P7) -> 38
A8: Ajuste a Presupuesto Máximo del Usuario | B8: 36 | I8: 3 | J8: 7 | K8: 6 | L8: 8 | M8: 7 | N8: 5 | Q8: =SUM(C8:P8) -> 36
A9: Integración del Motor con el Catálogo de Materiales | B9: 15 | N9: 2 | O9: 7 | P9: 7 | Q9: =SUM(C9:P9) -> 16
A12: Día (0 = inicio del sprint) | B12: 0 | C12: =C$4 -> 1 | D12: =D$4 -> 2 | E12: =E$4 -> 3 | F12: =F$4 -> 4 | G12: =G$4 -> 5 | H12: =H$4 -> 6 | I12: =I$4 -> 7 | J12: =J$4 -> 8 | ... P12: =P$4 -> 14
A13: Reales de producto por realizar | B13: =SUM(B6:B9) -> 91 | C13: =B13-SUM(C6:C9) -> 86 | D13: =C13-SUM(D6:D9) -> 81 | E13: =D13-SUM(E6:E9) -> 76 | F13: =E13-SUM(F6:F9) -> 69 | G13: =F13-SUM(G6:G9) -> 63 | H13: =G13-SUM(H6:H9) -> 56 | I13: =H13-SUM(I6:I9) -> 49 | J13: =I13-SUM(J6:J9) -> 42 | ... P13: =O13-SUM(P6:P9) -> 0
A15: Estimadas de producto por realizar | B15: =SUM(B6:B9) -> 91 | C15: =$B$15*(1-C$4/COUNT($C$4:$P$4)) -> 84.5 | D15: =$B$15*(1-D$4/COUNT($C$4:$P$4)) -> 78 | E15: =$B$15*(1-E$4/COUNT($C$4:$P$4)) -> 71.5 | F15: =$B$15*(1-F$4/COUNT($C$4:$P$4)) -> 65 | G15: =$B$15*(1-G$4/COUNT($C$4:$P$4)) -> 58.5 | H15: =$B$15*(1-H$4/COUNT($C$4:$P$4)) -> 52 | I15: =$B$15*(1-I$4/COUNT($C$4:$P$4)) -> 45.5 | J15: =$B$15*(1-J$4/COUNT($C$4:$P$4)) -> 39 | ... P15: =$B$15*(1-P$4/COUNT($C$4:$P$4)) -> 0

Sheet Sprint N°5
A1: ="Control del Sprint N°5 – "&Resumen_Sprints!B10 -> Control del Sprint N°5 – Interfaz Gráfica Interactiva
A3: Historias de Usuario o Spike | B3: horas estimadas | C3: DIA | S3: Total
C4: 1 | D4: 2 | E4: 3 | F4: 4 | G4: 5 | H4: 6 | I4: 7 | J4: 8 | K4: 9 | L4: 10 | M4: 11 | N4: 12 | O4: 13 | P4: 14 | Q4: 15 | R4: 16
A5: Interfaz Gráfica Interactiva | B5: =SUM(B6:B9) -> 97
A6: Coordinación del Objetivos Sprint 5 | B6: 1 | C6: 1 | S6: =SUM(C6:R6) -> 1
A7: Interfaz Principal y Formulario de Presupuesto | B7: 24 | C7: 4 | D7: 8 | E7: 5 | F7: 6 | G7: 1 | S7: =SUM(C7:R7) -> 24
A8: Editor Interactivo de Diseño del Hogar | B8: 49 | G8: 6 | H8: 5 | I8: 6 | J8: 4 | K8: 7 | L8: 7 | M8: 6 | N8: 7 | S8: =SUM(C8:R8) -> 48
A9: Visualización de Resultados en Tiempo Real | B9: 23 | O9: 5 | P9: 7 | Q9: 6 | R9: 6 | S9: =SUM(C9:R9) -> 24
A12: Día (0 = inicio del sprint) | B12: 0 | C12: =C$4 -> 1 | D12: =D$4 -> 2 | E12: =E$4 -> 3 | F12: =F$4 -> 4 | G12: =G$4 -> 5 | H12: =H$4 -> 6 | I12: =I$4 -> 7 | J12: =J$4 -> 8 | ... R12: =R$4 -> 16
A13: Reales de producto por realizar | B13: =SUM(B6:B9) -> 97 | C13: =B13-SUM(C6:C9) -> 92 | D13: =C13-SUM(D6:D9) -> 84 | E13: =D13-SUM(E6:E9) -> 79 | F13: =E13-SUM(F6:F9) -> 73 | G13: =F13-SUM(G6:G9) -> 66 | H13: =G13-SUM(H6:H9) -> 61 | I13: =H13-SUM(I6:I9) -> 55 | J13: =I13-SUM(J6:J9) -> 51 | ... R13: =Q13-SUM(R6:R9) -> 0
A15: Estimadas de producto por realizar | B15: =SUM(B6:B9) -> 97 | C15: =$B$15*(1-C$4/COUNT($C$4:$R$4)) -> 90.9375 | D15: =$B$15*(1-D$4/COUNT($C$4:$R$4)) -> 84.875 | E15: =$B$15*(1-E$4/COUNT($C$4:$R$4)) -> 78.8125 | F15: =$B$15*(1-F$4/COUNT($C$4:$R$4)) -> 72.75 | G15: =$B$15*(1-G$4/COUNT($C$4:$R$4)) -> 66.6875 | H15: =$B$15*(1-H$4/COUNT($C$4:$R$4)) -> 60.625 | I15: =$B$15*(1-I$4/COUNT($C$4:$R$4)) -> 54.5625 | J15: =$B$15*(1-J$4/COUNT($C$4:$R$4)) -> 48.5 | ... R15: =$B$15*(1-R$4/COUNT($C$4:$R$4)) -> 0

Sheet Sprint N°6
A1: ="Control del Sprint N°6 – "&Resumen_Sprints!B11 -> Control del Sprint N°6 – Proyección Monetaria, Integración y Ceremonias Scrum
A3: Historias de Usuario o Spike | B3: horas estimadas | C3: DIA | O3: Total
C4: 1 | D4: 2 | E4: 3 | F4: 4 | G4: 5 | H4: 6 | I4: 7 | J4: 8 | K4: 9 | L4: 10 | M4: 11 | N4: 12
A5: Proyección Monetaria, Integración y Ceremonias Scrum | B5: =SUM(B6:B10) -> 135
A6: Coordinación del componente | B6: 2 | C6: 1 | O6: =SUM(C6:N6) -> 1
A7: Generación de Proyección Monetaria del Hogar | B7: 27 | C7: 9 | D7: 13 | E7: 1 | O7: =SUM(C7:N7) -> 23
A8: Resumen y Exportación de Cotización | B8: 15 | E8: 12 | F8: 1 | O8: =SUM(C8:N8) -> 13
A9: Integración del Sistema | B9: 30 | F9: 10 | G9: 12 | H9: 6 | I9: 10 | O9: =SUM(C9:N9) -> 38
A10: Ceremonias Scrum (Planning, Review, Retrospectiva; en paralelo) | B10: 61 | I10: 3 | J10: 11 | K10: 15 | L10: 12 | M10: 9 | N10: 10 | O10: =SUM(C10:N10) -> 60
A13: Día (0 = inicio del sprint) | B13: 0 | C13: =C$4 -> 1 | D13: =D$4 -> 2 | E13: =E$4 -> 3 | F13: =F$4 -> 4 | G13: =G$4 -> 5 | H13: =H$4 -> 6 | I13: =I$4 -> 7 | J13: =J$4 -> 8 | ... N13: =N$4 -> 12
A14: Reales de producto por realizar | B14: =SUM(B6:B10) -> 135 | C14: =B14-SUM(C6:C10) -> 125 | D14: =C14-SUM(D6:D10) -> 112 | E14: =D14-SUM(E6:E10) -> 99 | F14: =E14-SUM(F6:F10) -> 88 | G14: =F14-SUM(G6:G10) -> 76 | H14: =G14-SUM(H6:H10) -> 70 | I14: =H14-SUM(I6:I10) -> 57 | J14: =I14-SUM(J6:J10) -> 46 | ... N14: =M14-SUM(N6:N10) -> 0
A16: Estimadas de producto por realizar | B16: =SUM(B6:B10) -> 135 | C16: =$B$16*(1-C$4/COUNT($C$4:$N$4)) -> 123.75 | D16: =$B$16*(1-D$4/COUNT($C$4:$N$4)) -> 112.5 | E16: =$B$16*(1-E$4/COUNT($C$4:$N$4)) -> 101.25 | F16: =$B$16*(1-F$4/COUNT($C$4:$N$4)) -> 90 | G16: =$B$16*(1-G$4/COUNT($C$4:$N$4)) -> 78.75 | H16: =$B$16*(1-H$4/COUNT($C$4:$N$4)) -> 67.5 | I16: =$B$16*(1-I$4/COUNT($C$4:$N$4)) -> 56.25 | J16: =$B$16*(1-J$4/COUNT($C$4:$N$4)) -> 45 | ... N16: =$B$16*(1-N$4/COUNT($C$4:$N$4)) -> 0

Sheet Sprint N°7
A1: ="Control del Sprint N°7 – "&Resumen_Sprints!B12 -> Control del Sprint N°7 – Pruebas y Corrección de Defectos
A3: Historias de Usuario o Spike | B3: horas estimadas | C3: DIA | Q3: Total
C4: 1 | D4: 2 | E4: 3 | F4: 4 | G4: 5 | H4: 6 | I4: 7 | J4: 8 | K4: 9 | L4: 10 | M4: 11 | N4: 12 | O4: 13 | P4: 14
A5: Pruebas y Corrección de Defectos | B5: =SUM(B6:B10) -> 114
A6: Pruebas Unitarias Base de Datos y Catálogo | B6: 16 | C6: 8 | D6: 7 | E6: 1 | Q6: =SUM(C6:P6) -> 16
A7: Pruebas Unitarias Motor de Cálculo | B7: 30 | E7: 6 | F7: 10 | G7: 8 | H7: 6 | Q7: =SUM(C7:P7) -> 30
A8: Pruebas Unitarias Interfaz Gráfica | B8: 14 | H8: 5 | I8: 9 | Q8: =SUM(C8:P8) -> 14
A9: Pruebas de Integración | B9: 24 | J9: 7 | K9: 8 | L9: 7 | M9: 2 | Q9: =SUM(C9:P9) -> 24
A10: Corrección de Defectos y Retesteo de Funcionalidades | B10: 30 | M10: 5 | N10: 8 | O10: 8 | P10: 9 | Q10: =SUM(C10:P10) -> 30
A13: Día (0 = inicio del sprint) | B13: 0 | C13: =C$4 -> 1 | D13: =D$4 -> 2 | E13: =E$4 -> 3 | F13: =F$4 -> 4 | G13: =G$4 -> 5 | H13: =H$4 -> 6 | I13: =I$4 -> 7 | J13: =J$4 -> 8 | ... P13: =P$4 -> 14
A14: Reales de producto por realizar | B14: =SUM(B6:B10) -> 114 | C14: =B14-SUM(C6:C10) -> 106 | D14: =C14-SUM(D6:D10) -> 99 | E14: =D14-SUM(E6:E10) -> 92 | F14: =E14-SUM(F6:F10) -> 82 | G14: =F14-SUM(G6:G10) -> 74 | H14: =G14-SUM(H6:H10) -> 63 | I14: =H14-SUM(I6:I10) -> 54 | J14: =I14-SUM(J6:J10) -> 47 | ... P14: =O14-SUM(P6:P10) -> 0
A16: Estimadas de producto por realizar | B16: =SUM(B6:B10) -> 114 | C16: =$B$16*(1-C$4/COUNT($C$4:$P$4)) -> 105.85714 | D16: =$B$16*(1-D$4/COUNT($C$4:$P$4)) -> 97.714286 | E16: =$B$16*(1-E$4/COUNT($C$4:$P$4)) -> 89.571429 | F16: =$B$16*(1-F$4/COUNT($C$4:$P$4)) -> 81.428571 | G16: =$B$16*(1-G$4/COUNT($C$4:$P$4)) -> 73.285714 | H16: =$B$16*(1-H$4/COUNT($C$4:$P$4)) -> 65.142857 | I16: =$B$16*(1-I$4/COUNT($C$4:$P$4)) -> 57 | J16: =$B$16*(1-J$4/COUNT($C$4:$P$4)) -> 48.857143 | ... P16: =$B$16*(1-P$4/COUNT($C$4:$P$4)) -> 0

Sheet Sprint N°8
A1: ="Control del Sprint N°8 – "&Resumen_Sprints!B13 -> Control del Sprint N°8 – Despliegue, Aceptación y Cierre
A3: Historias de Usuario o Spike | B3: horas estimadas | C3: DIA | N3: Total
C4: 1 | D4: 2 | E4: 3 | F4: 4 | G4: 5 | H4: 6 | I4: 7 | J4: 8 | K4: 9 | L4: 10 | M4: 11
A5: Despliegue, Aceptación y Cierre | B5: =SUM(B6:B10) -> 86
A6: Despliegue del Sistema a Producción | B6: 20 | C6: 7 | D6: 6 | E6: 2 | N6: =SUM(C6:M6) -> 15
A7: Pruebas de Aceptación con Patrocinadores | B7: 24 | E7: 6 | F7: 7 | G7: 5 | N7: =SUM(C7:M7) -> 18
A8: Marcha Blanca | B8: 29 | G8: 3 | H8: 8 | I8: 8 | J8: 6 | K8: 5 | N8: =SUM(C8:M8) -> 30
A9: Capacitación y Entrega | B9: 7 | K9: 4 | L9: 7 | N9: =SUM(C9:M9) -> 11
A10: Cierre de Proyecto | B10: 6 | L10: 1 | M10: 11 | N10: =SUM(C10:M10) -> 12
A13: Día (0 = inicio del sprint) | B13: 0 | C13: =C$4 -> 1 | D13: =D$4 -> 2 | E13: =E$4 -> 3 | F13: =F$4 -> 4 | G13: =G$4 -> 5 | H13: =H$4 -> 6 | I13: =I$4 -> 7 | J13: =J$4 -> 8 | ... M13: =M$4 -> 11
A14: Reales de producto por realizar | B14: =SUM(B6:B10) -> 86 | C14: =B14-SUM(C6:C10) -> 79 | D14: =C14-SUM(D6:D10) -> 73 | E14: =D14-SUM(E6:E10) -> 65 | F14: =E14-SUM(F6:F10) -> 58 | G14: =F14-SUM(G6:G10) -> 50 | H14: =G14-SUM(H6:H10) -> 42 | I14: =H14-SUM(I6:I10) -> 34 | J14: =I14-SUM(J6:J10) -> 28 | ... M14: =L14-SUM(M6:M10) -> 0
A16: Estimadas de producto por realizar | B16: =SUM(B6:B10) -> 86 | C16: =$B$16*(1-C$4/COUNT($C$4:$M$4)) -> 78.181818 | D16: =$B$16*(1-D$4/COUNT($C$4:$M$4)) -> 70.363636 | E16: =$B$16*(1-E$4/COUNT($C$4:$M$4)) -> 62.545455 | F16: =$B$16*(1-F$4/COUNT($C$4:$M$4)) -> 54.727273 | G16: =$B$16*(1-G$4/COUNT($C$4:$M$4)) -> 46.909091 | H16: =$B$16*(1-H$4/COUNT($C$4:$M$4)) -> 39.090909 | I16: =$B$16*(1-I$4/COUNT($C$4:$M$4)) -> 31.272727 | J16: =$B$16*(1-J$4/COUNT($C$4:$M$4)) -> 23.454545 | ... M16: =$B$16*(1-M$4/COUNT($C$4:$M$4)) -> 0

Sheet burndown_Proyecto_HouseCount
A1: Control del Proyecto HouseCount – Burndown acumulado
A2: Se alimenta de las hojas de cada sprint (no se ingresa nada aquí).
A3: Historias de Usuario o Spike | B3: horas estimadas | C3: DIA HÁBIL DEL PROYECTO | CU3: Total
C4: 1 | D4: 2 | E4: 3 | F4: 4 | G4: 5 | H4: 6 | I4: 7 | J4: 8 | K4: 9 | L4: 10 | M4: 11 | N4: 12 | O4: 13 | P4: 14 | Q4: 15 | R4: 16 | S4: 17 | T4: 18 | U4: 19 | V4: 20 | W4: 21 | X4: 22 | Y4: 23 | Z4: 24 | AA4: 25 | AB4: 26 | AC4: 27 | AD4: 28 | AE4: 29 | AF4: 30 | AG4: 31 | AH4: 32 | AI4: 33 | AJ4: 34 | AK4: 35 | AL4: 36 | AM4: 37 | AN4: 38 | AO4: 39 | AP4: 40 | AQ4: 41 | AR4: 42 | AS4: 43 | AT4: 44 | AU4: 45 | AV4: 46 | AW4: 47 | AX4: 48 | AY4: 49 | AZ4: 50 | BA4: 51 | BB4: 52 | BC4: 53 | BD4: 54 | BE4: 55 | BF4: 56 | BG4: 57 | BH4: 58 | BI4: 59 | BJ4: 60 | BK4: 61 | BL4: 62 | BM4: 63 | BN4: 64 | BO4: 65 | BP4: 66 | BQ4: 67 | BR4: 68 | BS4: 69 | BT4: 70 | BU4: 71 | BV4: 72 | BW4: 73 | BX4: 74 | BY4: 75 | BZ4: 76 | CA4: 77 | CB4: 78 | CC4: 79 | CD4: 80 | CE4: 81 | CF4: 82 | CG4: 83 | CH4: 84 | CI4: 85 | CJ4: 86 | CK4: 87 | CL4: 88 | CM4: 89 | CN4: 90 | CO4: 91 | CP4: 92 | CQ4: 93 | CR4: 94 | CS4: 95 | CT4: 96
A5: ="Sprint N°"&Resumen_Sprints!A6&" – "&Resumen_Sprints!B6 -> Sprint N°1 – Fase Análisis y Planificación | B5: =SUM(B6:B10) -> 43
A6: ='Sprint N°1'!A6 -> Kick Off | B6: ='Sprint N°1'!B6 -> 8 | C6: {=IF(AND(C$4>Resumen_Sprints!$E$6,C$4<=Resumen_Sprints!$E$6+Resumen_Sprints!$D$6),INDEX('Sprint N°1'!$C$6:$I$6,C$4-Resumen_Sprints!$E$6),0)} -> 7 | D6: {=IF(AND(D$4>Resumen_Sprints!$E$6,D$4<=Resumen_Sprints!$E$6+Resumen_Sprints!$D$6),INDEX('Sprint N°1'!$C$6:$I$6,D$4-Resumen_Sprints!$E$6),0)} -> 1 | E6: {=IF(AND(E$4>Resumen_Sprints!$E$6,E$4<=Resumen_Sprints!$E$6+Resumen_Sprints!$D$6),INDEX('Sprint N°1'!$C$6:$I$6,E$4-Resumen_Sprints!$E$6),0)} | F6: {=IF(AND(F$4>Resumen_Sprints!$E$6,F$4<=Resumen_Sprints!$E$6+Resumen_Sprints!$D$6),INDEX('Sprint N°1'!$C$6:$I$6,F$4-Resumen_Sprints!$E$6),0)} | G6: {=IF(AND(G$4>Resumen_Sprints!$E$6,G$4<=Resumen_Sprints!$E$6+Resumen_Sprints!$D$6),INDEX('Sprint N°1'!$C$6:$I$6,G$4-Resumen_Sprints!$E$6),0)} | H6: {=IF(AND(H$4>Resumen_Sprints!$E$6,H$4<=Resumen_Sprints!$E$6+Resumen_Sprints!$D$6),INDEX('Sprint N°1'!$C$6:$I$6,H$4-Resumen_Sprints!$E$6),0)} | I6: {=IF(AND(I$4>Resumen_Sprints!$E$6,I$4<=Resumen_Sprints!$E$6+Resumen_Sprints!$D$6),INDEX('Sprint N°1'!$C$6:$I$6,I$4-Resumen_Sprints!$E$6),0)} | J6: {=IF(AND(J$4>Resumen_Sprints!$E$6,J$4<=Resumen_Sprints!$E$6+Resumen_Sprints!$D$6),INDEX('Sprint N°1'!$C$6:$I$6,J$4-Resumen_Sprints!$E$6),0)} -> 0 | ... CT6: {=IF(AND(CT$4>Resumen_Sprints!$E$6,CT$4<=Resumen_Sprints!$E$6+Resumen_Sprints!$D$6),INDEX('Sprint N°1'!$C$6:$I$6,CT$4-Resumen_Sprints!$E$6),0)} -> 0 | CU6: =SUM(C6:CT6) -> 8
A7: ='Sprint N°1'!A7 -> Documento de Visión y Roles Scrum | B7: ='Sprint N°1'!B7 -> 8 | C7: {=IF(AND(C$4>Resumen_Sprints!$E$6,C$4<=Resumen_Sprints!$E$6+Resumen_Sprints!$D$6),INDEX('Sprint N°1'!$C$7:$I$7,C$4-Resumen_Sprints!$E$6),0)} | D7: {=IF(AND(D$4>Resumen_Sprints!$E$6,D$4<=Resumen_Sprints!$E$6+Resumen_Sprints!$D$6),INDEX('Sprint N°1'!$C$7:$I$7,D$4-Resumen_Sprints!$E$6),0)} -> 5 | E7: {=IF(AND(E$4>Resumen_Sprints!$E$6,E$4<=Resumen_Sprints!$E$6+Resumen_Sprints!$D$6),INDEX('Sprint N°1'!$C$7:$I$7,E$4-Resumen_Sprints!$E$6),0)} -> 3 | F7: {=IF(AND(F$4>Resumen_Sprints!$E$6,F$4<=Resumen_Sprints!$E$6+Resumen_Sprints!$D$6),INDEX('Sprint N°1'!$C$7:$I$7,F$4-Resumen_Sprints!$E$6),0)} | G7: {=IF(AND(G$4>Resumen_Sprints!$E$6,G$4<=Resumen_Sprints!$E$6+Resumen_Sprints!$D$6),INDEX('Sprint N°1'!$C$7:$I$7,G$4-Resumen_Sprints!$E$6),0)} | H7: {=IF(AND(H$4>Resumen_Sprints!$E$6,H$4<=Resumen_Sprints!$E$6+Resumen_Sprints!$D$6),INDEX('Sprint N°1'!$C$7:$I$7,H$4-Resumen_Sprints!$E$6),0)} | I7: {=IF(AND(I$4>Resumen_Sprints!$E$6,I$4<=Resumen_Sprints!$E$6+Resumen_Sprints!$D$6),INDEX('Sprint N°1'!$C$7:$I$7,I$4-Resumen_Sprints!$E$6),0)} | J7: {=IF(AND(J$4>Resumen_Sprints!$E$6,J$4<=Resumen_Sprints!$E$6+Resumen_Sprints!$D$6),INDEX('Sprint N°1'!$C$7:$I$7,J$4-Resumen_Sprints!$E$6),0)} -> 0 | ... CT7: {=IF(AND(CT$4>Resumen_Sprints!$E$6,CT$4<=Resumen_Sprints!$E$6+Resumen_Sprints!$D$6),INDEX('Sprint N°1'!$C$7:$I$7,CT$4-Resumen_Sprints!$E$6),0)} -> 0 | CU7: =SUM(C7:CT7) -> 8
A8: ='Sprint N°1'!A8 -> Aprobación de la Visión con Patrocinadores | B8: ='Sprint N°1'!B8 -> 1 | C8: {=IF(AND(C$4>Resumen_Sprints!$E$6,C$4<=Resumen_Sprints!$E$6+Resumen_Sprints!$D$6),INDEX('Sprint N°1'!$C$8:$I$8,C$4-Resumen_Sprints!$E$6),0)} | D8: {=IF(AND(D$4>Resumen_Sprints!$E$6,D$4<=Resumen_Sprints!$E$6+Resumen_Sprints!$D$6),INDEX('Sprint N°1'!$C$8:$I$8,D$4-Resumen_Sprints!$E$6),0)} | E8: {=IF(AND(E$4>Resumen_Sprints!$E$6,E$4<=Resumen_Sprints!$E$6+Resumen_Sprints!$D$6),INDEX('Sprint N°1'!$C$8:$I$8,E$4-Resumen_Sprints!$E$6),0)} -> 3 | F8: {=IF(AND(F$4>Resumen_Sprints!$E$6,F$4<=Resumen_Sprints!$E$6+Resumen_Sprints!$D$6),INDEX('Sprint N°1'!$C$8:$I$8,F$4-Resumen_Sprints!$E$6),0)} | G8: {=IF(AND(G$4>Resumen_Sprints!$E$6,G$4<=Resumen_Sprints!$E$6+Resumen_Sprints!$D$6),INDEX('Sprint N°1'!$C$8:$I$8,G$4-Resumen_Sprints!$E$6),0)} | H8: {=IF(AND(H$4>Resumen_Sprints!$E$6,H$4<=Resumen_Sprints!$E$6+Resumen_Sprints!$D$6),INDEX('Sprint N°1'!$C$8:$I$8,H$4-Resumen_Sprints!$E$6),0)} | I8: {=IF(AND(I$4>Resumen_Sprints!$E$6,I$4<=Resumen_Sprints!$E$6+Resumen_Sprints!$D$6),INDEX('Sprint N°1'!$C$8:$I$8,I$4-Resumen_Sprints!$E$6),0)} | J8: {=IF(AND(J$4>Resumen_Sprints!$E$6,J$4<=Resumen_Sprints!$E$6+Resumen_Sprints!$D$6),INDEX('Sprint N°1'!$C$8:$I$8,J$4-Resumen_Sprints!$E$6),0)} -> 0 | ... CT8: {=IF(AND(CT$4>Resumen_Sprints!$E$6,CT$4<=Resumen_Sprints!$E$6+Resumen_Sprints!$D$6),INDEX('Sprint N°1'!$C$8:$I$8,CT$4-Resumen_Sprints!$E$6),0)} -> 0 | CU8: =SUM(C8:CT8) -> 3
A9: ='Sprint N°1'!A9 -> Definición de Requerimientos Generales (Product Backlog inicial) | B9: ='Sprint N°1'!B9 -> 18 | C9: {=IF(AND(C$4>Resumen_Sprints!$E$6,C$4<=Resumen_Sprints!$E$6+Resumen_Sprints!$D$6),INDEX('Sprint N°1'!$C$9:$I$9,C$4-Resumen_Sprints!$E$6),0)} | D9: {=IF(AND(D$4>Resumen_Sprints!$E$6,D$4<=Resumen_Sprints!$E$6+Resumen_Sprints!$D$6),INDEX('Sprint N°1'!$C$9:$I$9,D$4-Resumen_Sprints!$E$6),0)} | E9: {=IF(AND(E$4>Resumen_Sprints!$E$6,E$4<=Resumen_Sprints!$E$6+Resumen_Sprints!$D$6),INDEX('Sprint N°1'!$C$9:$I$9,E$4-Resumen_Sprints!$E$6),0)} -> 1 | F9: {=IF(AND(F$4>Resumen_Sprints!$E$6,F$4<=Resumen_Sprints!$E$6+Resumen_Sprints!$D$6),INDEX('Sprint N°1'!$C$9:$I$9,F$4-Resumen_Sprints!$E$6),0)} -> 5 | G9: {=IF(AND(G$4>Resumen_Sprints!$E$6,G$4<=Resumen_Sprints!$E$6+Resumen_Sprints!$D$6),INDEX('Sprint N°1'!$C$9:$I$9,G$4-Resumen_Sprints!$E$6),0)} -> 7 | H9: {=IF(AND(H$4>Resumen_Sprints!$E$6,H$4<=Resumen_Sprints!$E$6+Resumen_Sprints!$D$6),INDEX('Sprint N°1'!$C$9:$I$9,H$4-Resumen_Sprints!$E$6),0)} -> 3 | I9: {=IF(AND(I$4>Resumen_Sprints!$E$6,I$4<=Resumen_Sprints!$E$6+Resumen_Sprints!$D$6),INDEX('Sprint N°1'!$C$9:$I$9,I$4-Resumen_Sprints!$E$6),0)} | J9: {=IF(AND(J$4>Resumen_Sprints!$E$6,J$4<=Resumen_Sprints!$E$6+Resumen_Sprints!$D$6),INDEX('Sprint N°1'!$C$9:$I$9,J$4-Resumen_Sprints!$E$6),0)} -> 0 | ... CT9: {=IF(AND(CT$4>Resumen_Sprints!$E$6,CT$4<=Resumen_Sprints!$E$6+Resumen_Sprints!$D$6),INDEX('Sprint N°1'!$C$9:$I$9,CT$4-Resumen_Sprints!$E$6),0)} -> 0 | CU9: =SUM(C9:CT9) -> 16
A10: ='Sprint N°1'!A10 -> Organización del Equipo y Herramientas (repositorio, tablero) | B10: ='Sprint N°1'!B10 -> 8 | C10: {=IF(AND(C$4>Resumen_Sprints!$E$6,C$4<=Resumen_Sprints!$E$6+Resumen_Sprints!$D$6),INDEX('Sprint N°1'!$C$10:$I$10,C$4-Resumen_Sprints!$E$6),0)} | D10: {=IF(AND(D$4>Resumen_Sprints!$E$6,D$4<=Resumen_Sprints!$E$6+Resumen_Sprints!$D$6),INDEX('Sprint N°1'!$C$10:$I$10,D$4-Resumen_Sprints!$E$6),0)} | E10: {=IF(AND(E$4>Resumen_Sprints!$E$6,E$4<=Resumen_Sprints!$E$6+Resumen_Sprints!$D$6),INDEX('Sprint N°1'!$C$10:$I$10,E$4-Resumen_Sprints!$E$6),0)} | F10: {=IF(AND(F$4>Resumen_Sprints!$E$6,F$4<=Resumen_Sprints!$E$6+Resumen_Sprints!$D$6),INDEX('Sprint N°1'!$C$10:$I$10,F$4-Resumen_Sprints!$E$6),0)} | G10: {=IF(AND(G$4>Resumen_Sprints!$E$6,G$4<=Resumen_Sprints!$E$6+Resumen_Sprints!$D$6),INDEX('Sprint N°1'!$C$10:$I$10,G$4-Resumen_Sprints!$E$6),0)} | H10: {=IF(AND(H$4>Resumen_Sprints!$E$6,H$4<=Resumen_Sprints!$E$6+Resumen_Sprints!$D$6),INDEX('Sprint N°1'!$C$10:$I$10,H$4-Resumen_Sprints!$E$6),0)} -> 3 | I10: {=IF(AND(I$4>Resumen_Sprints!$E$6,I$4<=Resumen_Sprints!$E$6+Resumen_Sprints!$D$6),INDEX('Sprint N°1'!$C$10:$I$10,I$4-Resumen_Sprints!$E$6),0)} -> 5 | J10: {=IF(AND(J$4>Resumen_Sprints!$E$6,J$4<=Resumen_Sprints!$E$6+Resumen_Sprints!$D$6),INDEX('Sprint N°1'!$C$10:$I$10,J$4-Resumen_Sprints!$E$6),0)} -> 0 | ... CT10: {=IF(AND(CT$4>Resumen_Sprints!$E$6,CT$4<=Resumen_Sprints!$E$6+Resumen_Sprints!$D$6),INDEX('Sprint N°1'!$C$10:$I$10,CT$4-Resumen_Sprints!$E$6),0)} -> 0 | CU10: =SUM(C10:CT10) -> 8
A11: ="Sprint N°"&Resumen_Sprints!A7&" – "&Resumen_Sprints!B7 -> Sprint N°2 – Fase Diseño | B11: =SUM(B12:B17) -> 98
A12: ='Sprint N°2'!A6 -> Captura de Requerimientos Específicos (Historias de Usuario) | B12: ='Sprint N°2'!B6 -> 16 | C12: {=IF(AND(C$4>Resumen_Sprints!$E$7,C$4<=Resumen_Sprints!$E$7+Resumen_Sprints!$D$7),INDEX('Sprint N°2'!$C$6:$O$6,C$4-Resumen_Sprints!$E$7),0)} -> 0 | D12: {=IF(AND(D$4>Resumen_Sprints!$E$7,D$4<=Resumen_Sprints!$E$7+Resumen_Sprints!$D$7),INDEX('Sprint N°2'!$C$6:$O$6,D$4-Resumen_Sprints!$E$7),0)} -> 0 | E12: {=IF(AND(E$4>Resumen_Sprints!$E$7,E$4<=Resumen_Sprints!$E$7+Resumen_Sprints!$D$7),INDEX('Sprint N°2'!$C$6:$O$6,E$4-Resumen_Sprints!$E$7),0)} -> 0 | F12: {=IF(AND(F$4>Resumen_Sprints!$E$7,F$4<=Resumen_Sprints!$E$7+Resumen_Sprints!$D$7),INDEX('Sprint N°2'!$C$6:$O$6,F$4-Resumen_Sprints!$E$7),0)} -> 0 | G12: {=IF(AND(G$4>Resumen_Sprints!$E$7,G$4<=Resumen_Sprints!$E$7+Resumen_Sprints!$D$7),INDEX('Sprint N°2'!$C$6:$O$6,G$4-Resumen_Sprints!$E$7),0)} -> 0 | H12: {=IF(AND(H$4>Resumen_Sprints!$E$7,H$4<=Resumen_Sprints!$E$7+Resumen_Sprints!$D$7),INDEX('Sprint N°2'!$C$6:$O$6,H$4-Resumen_Sprints!$E$7),0)} -> 0 | I12: {=IF(AND(I$4>Resumen_Sprints!$E$7,I$4<=Resumen_Sprints!$E$7+Resumen_Sprints!$D$7),INDEX('Sprint N°2'!$C$6:$O$6,I$4-Resumen_Sprints!$E$7),0)} -> 0 | J12: {=IF(AND(J$4>Resumen_Sprints!$E$7,J$4<=Resumen_Sprints!$E$7+Resumen_Sprints!$D$7),INDEX('Sprint N°2'!$C$6:$O$6,J$4-Resumen_Sprints!$E$7),0)} -> 7 | ... CT12: {=IF(AND(CT$4>Resumen_Sprints!$E$7,CT$4<=Resumen_Sprints!$E$7+Resumen_Sprints!$D$7),INDEX('Sprint N°2'!$C$6:$O$6,CT$4-Resumen_Sprints!$E$7),0)} -> 0 | CU12: =SUM(C12:CT12) -> 16
A13: ='Sprint N°2'!A7 -> Análisis de Requerimientos y Criterios de Aceptación | B13: ='Sprint N°2'!B7 -> 14 | C13: {=IF(AND(C$4>Resumen_Sprints!$E$7,C$4<=Resumen_Sprints!$E$7+Resumen_Sprints!$D$7),INDEX('Sprint N°2'!$C$7:$O$7,C$4-Resumen_Sprints!$E$7),0)} -> 0 | D13: {=IF(AND(D$4>Resumen_Sprints!$E$7,D$4<=Resumen_Sprints!$E$7+Resumen_Sprints!$D$7),INDEX('Sprint N°2'!$C$7:$O$7,D$4-Resumen_Sprints!$E$7),0)} -> 0 | E13: {=IF(AND(E$4>Resumen_Sprints!$E$7,E$4<=Resumen_Sprints!$E$7+Resumen_Sprints!$D$7),INDEX('Sprint N°2'!$C$7:$O$7,E$4-Resumen_Sprints!$E$7),0)} -> 0 | F13: {=IF(AND(F$4>Resumen_Sprints!$E$7,F$4<=Resumen_Sprints!$E$7+Resumen_Sprints!$D$7),INDEX('Sprint N°2'!$C$7:$O$7,F$4-Resumen_Sprints!$E$7),0)} -> 0 | G13: {=IF(AND(G$4>Resumen_Sprints!$E$7,G$4<=Resumen_Sprints!$E$7+Resumen_Sprints!$D$7),INDEX('Sprint N°2'!$C$7:$O$7,G$4-Resumen_Sprints!$E$7),0)} -> 0 | H13: {=IF(AND(H$4>Resumen_Sprints!$E$7,H$4<=Resumen_Sprints!$E$7+Resumen_Sprints!$D$7),INDEX('Sprint N°2'!$C$7:$O$7,H$4-Resumen_Sprints!$E$7),0)} -> 0 | I13: {=IF(AND(I$4>Resumen_Sprints!$E$7,I$4<=Resumen_Sprints!$E$7+Resumen_Sprints!$D$7),INDEX('Sprint N°2'!$C$7:$O$7,I$4-Resumen_Sprints!$E$7),0)} -> 0 | J13: {=IF(AND(J$4>Resumen_Sprints!$E$7,J$4<=Resumen_Sprints!$E$7+Resumen_Sprints!$D$7),INDEX('Sprint N°2'!$C$7:$O$7,J$4-Resumen_Sprints!$E$7),0)} | ... CT13: {=IF(AND(CT$4>Resumen_Sprints!$E$7,CT$4<=Resumen_Sprints!$E$7+Resumen_Sprints!$D$7),INDEX('Sprint N°2'!$C$7:$O$7,CT$4-Resumen_Sprints!$E$7),0)} -> 0 | CU13: =SUM(C13:CT13) -> 14
A14: ='Sprint N°2'!A8 -> Diseño de la Solución. Modelo de Datos y UML | B14: ='Sprint N°2'!B8 -> 23 | C14: {=IF(AND(C$4>Resumen_Sprints!$E$7,C$4<=Resumen_Sprints!$E$7+Resumen_Sprints!$D$7),INDEX('Sprint N°2'!$C$8:$O$8,C$4-Resumen_Sprints!$E$7),0)} -> 0 | D14: {=IF(AND(D$4>Resumen_Sprints!$E$7,D$4<=Resumen_Sprints!$E$7+Resumen_Sprints!$D$7),INDEX('Sprint N°2'!$C$8:$O$8,D$4-Resumen_Sprints!$E$7),0)} -> 0 | E14: {=IF(AND(E$4>Resumen_Sprints!$E$7,E$4<=Resumen_Sprints!$E$7+Resumen_Sprints!$D$7),INDEX('Sprint N°2'!$C$8:$O$8,E$4-Resumen_Sprints!$E$7),0)} -> 0 | F14: {=IF(AND(F$4>Resumen_Sprints!$E$7,F$4<=Resumen_Sprints!$E$7+Resumen_Sprints!$D$7),INDEX('Sprint N°2'!$C$8:$O$8,F$4-Resumen_Sprints!$E$7),0)} -> 0 | G14: {=IF(AND(G$4>Resumen_Sprints!$E$7,G$4<=Resumen_Sprints!$E$7+Resumen_Sprints!$D$7),INDEX('Sprint N°2'!$C$8:$O$8,G$4-Resumen_Sprints!$E$7),0)} -> 0 | H14: {=IF(AND(H$4>Resumen_Sprints!$E$7,H$4<=Resumen_Sprints!$E$7+Resumen_Sprints!$D$7),INDEX('Sprint N°2'!$C$8:$O$8,H$4-Resumen_Sprints!$E$7),0)} -> 0 | I14: {=IF(AND(I$4>Resumen_Sprints!$E$7,I$4<=Resumen_Sprints!$E$7+Resumen_Sprints!$D$7),INDEX('Sprint N°2'!$C$8:$O$8,I$4-Resumen_Sprints!$E$7),0)} -> 0 | J14: {=IF(AND(J$4>Resumen_Sprints!$E$7,J$4<=Resumen_Sprints!$E$7+Resumen_Sprints!$D$7),INDEX('Sprint N°2'!$C$8:$O$8,J$4-Resumen_Sprints!$E$7),0)} | ... CT14: {=IF(AND(CT$4>Resumen_Sprints!$E$7,CT$4<=Resumen_Sprints!$E$7+Resumen_Sprints!$D$7),INDEX('Sprint N°2'!$C$8:$O$8,CT$4-Resumen_Sprints!$E$7),0)} -> 0 | CU14: =SUM(C14:CT14) -> 22
A15: ='Sprint N°2'!A9 -> Diseño de Prototipos de Interfaz | B15: ='Sprint N°2'!B9 -> 18 | C15: {=IF(AND(C$4>Resumen_Sprints!$E$7,C$4<=Resumen_Sprints!$E$7+Resumen_Sprints!$D$7),INDEX('Sprint N°2'!$C$9:$O$9,C$4-Resumen_Sprints!$E$7),0)} -> 0 | D15: {=IF(AND(D$4>Resumen_Sprints!$E$7,D$4<=Resumen_Sprints!$E$7+Resumen_Sprints!$D$7),INDEX('Sprint N°2'!$C$9:$O$9,D$4-Resumen_Sprints!$E$7),0)} -> 0 | E15: {=IF(AND(E$4>Resumen_Sprints!$E$7,E$4<=Resumen_Sprints!$E$7+Resumen_Sprints!$D$7),INDEX('Sprint N°2'!$C$9:$O$9,E$4-Resumen_Sprints!$E$7),0)} -> 0 | F15: {=IF(AND(F$4>Resumen_Sprints!$E$7,F$4<=Resumen_Sprints!$E$7+Resumen_Sprints!$D$7),INDEX('Sprint N°2'!$C$9:$O$9,F$4-Resumen_Sprints!$E$7),0)} -> 0 | G15: {=IF(AND(G$4>Resumen_Sprints!$E$7,G$4<=Resumen_Sprints!$E$7+Resumen_Sprints!$D$7),INDEX('Sprint N°2'!$C$9:$O$9,G$4-Resumen_Sprints!$E$7),0)} -> 0 | H15: {=IF(AND(H$4>Resumen_Sprints!$E$7,H$4<=Resumen_Sprints!$E$7+Resumen_Sprints!$D$7),INDEX('Sprint N°2'!$C$9:$O$9,H$4-Resumen_Sprints!$E$7),0)} -> 0 | I15: {=IF(AND(I$4>Resumen_Sprints!$E$7,I$4<=Resumen_Sprints!$E$7+Resumen_Sprints!$D$7),INDEX('Sprint N°2'!$C$9:$O$9,I$4-Resumen_Sprints!$E$7),0)} -> 0 | J15: {=IF(AND(J$4>Resumen_Sprints!$E$7,J$4<=Resumen_Sprints!$E$7+Resumen_Sprints!$D$7),INDEX('Sprint N°2'!$C$9:$O$9,J$4-Resumen_Sprints!$E$7),0)} | ... CT15: {=IF(AND(CT$4>Resumen_Sprints!$E$7,CT$4<=Resumen_Sprints!$E$7+Resumen_Sprints!$D$7),INDEX('Sprint N°2'!$C$9:$O$9,CT$4-Resumen_Sprints!$E$7),0)} -> 0 | CU15: =SUM(C15:CT15) -> 18
A16: ='Sprint N°2'!A10 -> Diseño del Algoritmo de Cubicación | B16: ='Sprint N°2'!B10 -> 11 | C16: {=IF(AND(C$4>Resumen_Sprints!$E$7,C$4<=Resumen_Sprints!$E$7+Resumen_Sprints!$D$7),INDEX('Sprint N°2'!$C$10:$O$10,C$4-Resumen_Sprints!$E$7),0)} -> 0 | D16: {=IF(AND(D$4>Resumen_Sprints!$E$7,D$4<=Resumen_Sprints!$E$7+Resumen_Sprints!$D$7),INDEX('Sprint N°2'!$C$10:$O$10,D$4-Resumen_Sprints!$E$7),0)} -> 0 | E16: {=IF(AND(E$4>Resumen_Sprints!$E$7,E$4<=Resumen_Sprints!$E$7+Resumen_Sprints!$D$7),INDEX('Sprint N°2'!$C$10:$O$10,E$4-Resumen_Sprints!$E$7),0)} -> 0 | F16: {=IF(AND(F$4>Resumen_Sprints!$E$7,F$4<=Resumen_Sprints!$E$7+Resumen_Sprints!$D$7),INDEX('Sprint N°2'!$C$10:$O$10,F$4-Resumen_Sprints!$E$7),0)} -> 0 | G16: {=IF(AND(G$4>Resumen_Sprints!$E$7,G$4<=Resumen_Sprints!$E$7+Resumen_Sprints!$D$7),INDEX('Sprint N°2'!$C$10:$O$10,G$4-Resumen_Sprints!$E$7),0)} -> 0 | H16: {=IF(AND(H$4>Resumen_Sprints!$E$7,H$4<=Resumen_Sprints!$E$7+Resumen_Sprints!$D$7),INDEX('Sprint N°2'!$C$10:$O$10,H$4-Resumen_Sprints!$E$7),0)} -> 0 | I16: {=IF(AND(I$4>Resumen_Sprints!$E$7,I$4<=Resumen_Sprints!$E$7+Resumen_Sprints!$D$7),INDEX('Sprint N°2'!$C$10:$O$10,I$4-Resumen_Sprints!$E$7),0)} -> 0 | J16: {=IF(AND(J$4>Resumen_Sprints!$E$7,J$4<=Resumen_Sprints!$E$7+Resumen_Sprints!$D$7),INDEX('Sprint N°2'!$C$10:$O$10,J$4-Resumen_Sprints!$E$7),0)} | ... CT16: {=IF(AND(CT$4>Resumen_Sprints!$E$7,CT$4<=Resumen_Sprints!$E$7+Resumen_Sprints!$D$7),INDEX('Sprint N°2'!$C$10:$O$10,CT$4-Resumen_Sprints!$E$7),0)} -> 0 | CU16: =SUM(C16:CT16) -> 12
A17: ='Sprint N°2'!A11 -> Plan de Proyecto y Product Backlog Priorizado | B17: ='Sprint N°2'!B11 -> 16 | C17: {=IF(AND(C$4>Resumen_Sprints!$E$7,C$4<=Resumen_Sprints!$E$7+Resumen_Sprints!$D$7),INDEX('Sprint N°2'!$C$11:$O$11,C$4-Resumen_Sprints!$E$7),0)} -> 0 | D17: {=IF(AND(D$4>Resumen_Sprints!$E$7,D$4<=Resumen_Sprints!$E$7+Resumen_Sprints!$D$7),INDEX('Sprint N°2'!$C$11:$O$11,D$4-Resumen_Sprints!$E$7),0)} -> 0 | E17: {=IF(AND(E$4>Resumen_Sprints!$E$7,E$4<=Resumen_Sprints!$E$7+Resumen_Sprints!$D$7),INDEX('Sprint N°2'!$C$11:$O$11,E$4-Resumen_Sprints!$E$7),0)} -> 0 | F17: {=IF(AND(F$4>Resumen_Sprints!$E$7,F$4<=Resumen_Sprints!$E$7+Resumen_Sprints!$D$7),INDEX('Sprint N°2'!$C$11:$O$11,F$4-Resumen_Sprints!$E$7),0)} -> 0 | G17: {=IF(AND(G$4>Resumen_Sprints!$E$7,G$4<=Resumen_Sprints!$E$7+Resumen_Sprints!$D$7),INDEX('Sprint N°2'!$C$11:$O$11,G$4-Resumen_Sprints!$E$7),0)} -> 0 | H17: {=IF(AND(H$4>Resumen_Sprints!$E$7,H$4<=Resumen_Sprints!$E$7+Resumen_Sprints!$D$7),INDEX('Sprint N°2'!$C$11:$O$11,H$4-Resumen_Sprints!$E$7),0)} -> 0 | I17: {=IF(AND(I$4>Resumen_Sprints!$E$7,I$4<=Resumen_Sprints!$E$7+Resumen_Sprints!$D$7),INDEX('Sprint N°2'!$C$11:$O$11,I$4-Resumen_Sprints!$E$7),0)} -> 0 | J17: {=IF(AND(J$4>Resumen_Sprints!$E$7,J$4<=Resumen_Sprints!$E$7+Resumen_Sprints!$D$7),INDEX('Sprint N°2'!$C$11:$O$11,J$4-Resumen_Sprints!$E$7),0)} | ... CT17: {=IF(AND(CT$4>Resumen_Sprints!$E$7,CT$4<=Resumen_Sprints!$E$7+Resumen_Sprints!$D$7),INDEX('Sprint N°2'!$C$11:$O$11,CT$4-Resumen_Sprints!$E$7),0)} -> 0 | CU17: =SUM(C17:CT17) -> 16
A18: ="Sprint N°"&Resumen_Sprints!A8&" – "&Resumen_Sprints!B8 -> Sprint N°3 – Base de Datos y Catálogo de Materiales | B18: =SUM(B19:B22) -> 47
A19: ='Sprint N°3'!A6 -> Coordinación del Objetivos Sprint 3 | B19: ='Sprint N°3'!B6 -> 1 | C19: {=IF(AND(C$4>Resumen_Sprints!$E$8,C$4<=Resumen_Sprints!$E$8+Resumen_Sprints!$D$8),INDEX('Sprint N°3'!$C$6:$I$6,C$4-Resumen_Sprints!$E$8),0)} -> 0 | D19: {=IF(AND(D$4>Resumen_Sprints!$E$8,D$4<=Resumen_Sprints!$E$8+Resumen_Sprints!$D$8),INDEX('Sprint N°3'!$C$6:$I$6,D$4-Resumen_Sprints!$E$8),0)} -> 0 | E19: {=IF(AND(E$4>Resumen_Sprints!$E$8,E$4<=Resumen_Sprints!$E$8+Resumen_Sprints!$D$8),INDEX('Sprint N°3'!$C$6:$I$6,E$4-Resumen_Sprints!$E$8),0)} -> 0 | F19: {=IF(AND(F$4>Resumen_Sprints!$E$8,F$4<=Resumen_Sprints!$E$8+Resumen_Sprints!$D$8),INDEX('Sprint N°3'!$C$6:$I$6,F$4-Resumen_Sprints!$E$8),0)} -> 0 | G19: {=IF(AND(G$4>Resumen_Sprints!$E$8,G$4<=Resumen_Sprints!$E$8+Resumen_Sprints!$D$8),INDEX('Sprint N°3'!$C$6:$I$6,G$4-Resumen_Sprints!$E$8),0)} -> 0 | H19: {=IF(AND(H$4>Resumen_Sprints!$E$8,H$4<=Resumen_Sprints!$E$8+Resumen_Sprints!$D$8),INDEX('Sprint N°3'!$C$6:$I$6,H$4-Resumen_Sprints!$E$8),0)} -> 0 | I19: {=IF(AND(I$4>Resumen_Sprints!$E$8,I$4<=Resumen_Sprints!$E$8+Resumen_Sprints!$D$8),INDEX('Sprint N°3'!$C$6:$I$6,I$4-Resumen_Sprints!$E$8),0)} -> 0 | J19: {=IF(AND(J$4>Resumen_Sprints!$E$8,J$4<=Resumen_Sprints!$E$8+Resumen_Sprints!$D$8),INDEX('Sprint N°3'!$C$6:$I$6,J$4-Resumen_Sprints!$E$8),0)} -> 0 | ... CT19: {=IF(AND(CT$4>Resumen_Sprints!$E$8,CT$4<=Resumen_Sprints!$E$8+Resumen_Sprints!$D$8),INDEX('Sprint N°3'!$C$6:$I$6,CT$4-Resumen_Sprints!$E$8),0)} -> 0 | CU19: =SUM(C19:CT19) -> 1
A20: ='Sprint N°3'!A7 -> Implementación del Ambiente de Desarrollo | B20: ='Sprint N°3'!B7 -> 10 | C20: {=IF(AND(C$4>Resumen_Sprints!$E$8,C$4<=Resumen_Sprints!$E$8+Resumen_Sprints!$D$8),INDEX('Sprint N°3'!$C$7:$I$7,C$4-Resumen_Sprints!$E$8),0)} -> 0 | D20: {=IF(AND(D$4>Resumen_Sprints!$E$8,D$4<=Resumen_Sprints!$E$8+Resumen_Sprints!$D$8),INDEX('Sprint N°3'!$C$7:$I$7,D$4-Resumen_Sprints!$E$8),0)} -> 0 | E20: {=IF(AND(E$4>Resumen_Sprints!$E$8,E$4<=Resumen_Sprints!$E$8+Resumen_Sprints!$D$8),INDEX('Sprint N°3'!$C$7:$I$7,E$4-Resumen_Sprints!$E$8),0)} -> 0 | F20: {=IF(AND(F$4>Resumen_Sprints!$E$8,F$4<=Resumen_Sprints!$E$8+Resumen_Sprints!$D$8),INDEX('Sprint N°3'!$C$7:$I$7,F$4-Resumen_Sprints!$E$8),0)} -> 0 | G20: {=IF(AND(G$4>Resumen_Sprints!$E$8,G$4<=Resumen_Sprints!$E$8+Resumen_Sprints!$D$8),INDEX('Sprint N°3'!$C$7:$I$7,G$4-Resumen_Sprints!$E$8),0)} -> 0 | H20: {=IF(AND(H$4>Resumen_Sprints!$E$8,H$4<=Resumen_Sprints!$E$8+Resumen_Sprints!$D$8),INDEX('Sprint N°3'!$C$7:$I$7,H$4-Resumen_Sprints!$E$8),0)} -> 0 | I20: {=IF(AND(I$4>Resumen_Sprints!$E$8,I$4<=Resumen_Sprints!$E$8+Resumen_Sprints!$D$8),INDEX('Sprint N°3'!$C$7:$I$7,I$4-Resumen_Sprints!$E$8),0)} -> 0 | J20: {=IF(AND(J$4>Resumen_Sprints!$E$8,J$4<=Resumen_Sprints!$E$8+Resumen_Sprints!$D$8),INDEX('Sprint N°3'!$C$7:$I$7,J$4-Resumen_Sprints!$E$8),0)} -> 0 | ... CT20: {=IF(AND(CT$4>Resumen_Sprints!$E$8,CT$4<=Resumen_Sprints!$E$8+Resumen_Sprints!$D$8),INDEX('Sprint N°3'!$C$7:$I$7,CT$4-Resumen_Sprints!$E$8),0)} -> 0 | CU20: =SUM(C20:CT20) -> 10
A21: ='Sprint N°3'!A8 -> Modelo Relacional de Base de Datos | B21: ='Sprint N°3'!B8 -> 19 | C21: {=IF(AND(C$4>Resumen_Sprints!$E$8,C$4<=Resumen_Sprints!$E$8+Resumen_Sprints!$D$8),INDEX('Sprint N°3'!$C$8:$I$8,C$4-Resumen_Sprints!$E$8),0)} -> 0 | D21: {=IF(AND(D$4>Resumen_Sprints!$E$8,D$4<=Resumen_Sprints!$E$8+Resumen_Sprints!$D$8),INDEX('Sprint N°3'!$C$8:$I$8,D$4-Resumen_Sprints!$E$8),0)} -> 0 | E21: {=IF(AND(E$4>Resumen_Sprints!$E$8,E$4<=Resumen_Sprints!$E$8+Resumen_Sprints!$D$8),INDEX('Sprint N°3'!$C$8:$I$8,E$4-Resumen_Sprints!$E$8),0)} -> 0 | F21: {=IF(AND(F$4>Resumen_Sprints!$E$8,F$4<=Resumen_Sprints!$E$8+Resumen_Sprints!$D$8),INDEX('Sprint N°3'!$C$8:$I$8,F$4-Resumen_Sprints!$E$8),0)} -> 0 | G21: {=IF(AND(G$4>Resumen_Sprints!$E$8,G$4<=Resumen_Sprints!$E$8+Resumen_Sprints!$D$8),INDEX('Sprint N°3'!$C$8:$I$8,G$4-Resumen_Sprints!$E$8),0)} -> 0 | H21: {=IF(AND(H$4>Resumen_Sprints!$E$8,H$4<=Resumen_Sprints!$E$8+Resumen_Sprints!$D$8),INDEX('Sprint N°3'!$C$8:$I$8,H$4-Resumen_Sprints!$E$8),0)} -> 0 | I21: {=IF(AND(I$4>Resumen_Sprints!$E$8,I$4<=Resumen_Sprints!$E$8+Resumen_Sprints!$D$8),INDEX('Sprint N°3'!$C$8:$I$8,I$4-Resumen_Sprints!$E$8),0)} -> 0 | J21: {=IF(AND(J$4>Resumen_Sprints!$E$8,J$4<=Resumen_Sprints!$E$8+Resumen_Sprints!$D$8),INDEX('Sprint N°3'!$C$8:$I$8,J$4-Resumen_Sprints!$E$8),0)} -> 0 | ... CT21: {=IF(AND(CT$4>Resumen_Sprints!$E$8,CT$4<=Resumen_Sprints!$E$8+Resumen_Sprints!$D$8),INDEX('Sprint N°3'!$C$8:$I$8,CT$4-Resumen_Sprints!$E$8),0)} -> 0 | CU21: =SUM(C21:CT21) -> 19
A22: ='Sprint N°3'!A9 -> Catálogo de Materiales y Poblamiento Inicial | B22: ='Sprint N°3'!B9 -> 17 | C22: {=IF(AND(C$4>Resumen_Sprints!$E$8,C$4<=Resumen_Sprints!$E$8+Resumen_Sprints!$D$8),INDEX('Sprint N°3'!$C$9:$I$9,C$4-Resumen_Sprints!$E$8),0)} -> 0 | D22: {=IF(AND(D$4>Resumen_Sprints!$E$8,D$4<=Resumen_Sprints!$E$8+Resumen_Sprints!$D$8),INDEX('Sprint N°3'!$C$9:$I$9,D$4-Resumen_Sprints!$E$8),0)} -> 0 | E22: {=IF(AND(E$4>Resumen_Sprints!$E$8,E$4<=Resumen_Sprints!$E$8+Resumen_Sprints!$D$8),INDEX('Sprint N°3'!$C$9:$I$9,E$4-Resumen_Sprints!$E$8),0)} -> 0 | F22: {=IF(AND(F$4>Resumen_Sprints!$E$8,F$4<=Resumen_Sprints!$E$8+Resumen_Sprints!$D$8),INDEX('Sprint N°3'!$C$9:$I$9,F$4-Resumen_Sprints!$E$8),0)} -> 0 | G22: {=IF(AND(G$4>Resumen_Sprints!$E$8,G$4<=Resumen_Sprints!$E$8+Resumen_Sprints!$D$8),INDEX('Sprint N°3'!$C$9:$I$9,G$4-Resumen_Sprints!$E$8),0)} -> 0 | H22: {=IF(AND(H$4>Resumen_Sprints!$E$8,H$4<=Resumen_Sprints!$E$8+Resumen_Sprints!$D$8),INDEX('Sprint N°3'!$C$9:$I$9,H$4-Resumen_Sprints!$E$8),0)} -> 0 | I22: {=IF(AND(I$4>Resumen_Sprints!$E$8,I$4<=Resumen_Sprints!$E$8+Resumen_Sprints!$D$8),INDEX('Sprint N°3'!$C$9:$I$9,I$4-Resumen_Sprints!$E$8),0)} -> 0 | J22: {=IF(AND(J$4>Resumen_Sprints!$E$8,J$4<=Resumen_Sprints!$E$8+Resumen_Sprints!$D$8),INDEX('Sprint N°3'!$C$9:$I$9,J$4-Resumen_Sprints!$E$8),0)} -> 0 | ... CT22: {=IF(AND(CT$4>Resumen_Sprints!$E$8,CT$4<=Resumen_Sprints!$E$8+Resumen_Sprints!$D$8),INDEX('Sprint N°3'!$C$9:$I$9,CT$4-Resumen_Sprints!$E$8),0)} -> 0 | CU22: =SUM(C22:CT22) -> 17
A23: ="Sprint N°"&Resumen_Sprints!A9&" – "&Resumen_Sprints!B9 -> Sprint N°4 – Motor de Simulación y Algoritmo de Cálculo | B23: =SUM(B24:B27) -> 91
A24: ='Sprint N°4'!A6 -> Coordinación delObjetivos Sprint 4 | B24: ='Sprint N°4'!B6 -> 1 | C24: {=IF(AND(C$4>Resumen_Sprints!$E$9,C$4<=Resumen_Sprints!$E$9+Resumen_Sprints!$D$9),INDEX('Sprint N°4'!$C$6:$P$6,C$4-Resumen_Sprints!$E$9),0)} -> 0 | D24: {=IF(AND(D$4>Resumen_Sprints!$E$9,D$4<=Resumen_Sprints!$E$9+Resumen_Sprints!$D$9),INDEX('Sprint N°4'!$C$6:$P$6,D$4-Resumen_Sprints!$E$9),0)} -> 0 | E24: {=IF(AND(E$4>Resumen_Sprints!$E$9,E$4<=Resumen_Sprints!$E$9+Resumen_Sprints!$D$9),INDEX('Sprint N°4'!$C$6:$P$6,E$4-Resumen_Sprints!$E$9),0)} -> 0 | F24: {=IF(AND(F$4>Resumen_Sprints!$E$9,F$4<=Resumen_Sprints!$E$9+Resumen_Sprints!$D$9),INDEX('Sprint N°4'!$C$6:$P$6,F$4-Resumen_Sprints!$E$9),0)} -> 0 | G24: {=IF(AND(G$4>Resumen_Sprints!$E$9,G$4<=Resumen_Sprints!$E$9+Resumen_Sprints!$D$9),INDEX('Sprint N°4'!$C$6:$P$6,G$4-Resumen_Sprints!$E$9),0)} -> 0 | H24: {=IF(AND(H$4>Resumen_Sprints!$E$9,H$4<=Resumen_Sprints!$E$9+Resumen_Sprints!$D$9),INDEX('Sprint N°4'!$C$6:$P$6,H$4-Resumen_Sprints!$E$9),0)} -> 0 | I24: {=IF(AND(I$4>Resumen_Sprints!$E$9,I$4<=Resumen_Sprints!$E$9+Resumen_Sprints!$D$9),INDEX('Sprint N°4'!$C$6:$P$6,I$4-Resumen_Sprints!$E$9),0)} -> 0 | J24: {=IF(AND(J$4>Resumen_Sprints!$E$9,J$4<=Resumen_Sprints!$E$9+Resumen_Sprints!$D$9),INDEX('Sprint N°4'!$C$6:$P$6,J$4-Resumen_Sprints!$E$9),0)} -> 0 | ... CT24: {=IF(AND(CT$4>Resumen_Sprints!$E$9,CT$4<=Resumen_Sprints!$E$9+Resumen_Sprints!$D$9),INDEX('Sprint N°4'!$C$6:$P$6,CT$4-Resumen_Sprints!$E$9),0)} -> 0 | CU24: =SUM(C24:CT24) -> 1
A25: ='Sprint N°4'!A7 -> Algoritmo de Cubicación (cálculo de materiales) | B25: ='Sprint N°4'!B7 -> 39 | C25: {=IF(AND(C$4>Resumen_Sprints!$E$9,C$4<=Resumen_Sprints!$E$9+Resumen_Sprints!$D$9),INDEX('Sprint N°4'!$C$7:$P$7,C$4-Resumen_Sprints!$E$9),0)} -> 0 | D25: {=IF(AND(D$4>Resumen_Sprints!$E$9,D$4<=Resumen_Sprints!$E$9+Resumen_Sprints!$D$9),INDEX('Sprint N°4'!$C$7:$P$7,D$4-Resumen_Sprints!$E$9),0)} -> 0 | E25: {=IF(AND(E$4>Resumen_Sprints!$E$9,E$4<=Resumen_Sprints!$E$9+Resumen_Sprints!$D$9),INDEX('Sprint N°4'!$C$7:$P$7,E$4-Resumen_Sprints!$E$9),0)} -> 0 | F25: {=IF(AND(F$4>Resumen_Sprints!$E$9,F$4<=Resumen_Sprints!$E$9+Resumen_Sprints!$D$9),INDEX('Sprint N°4'!$C$7:$P$7,F$4-Resumen_Sprints!$E$9),0)} -> 0 | G25: {=IF(AND(G$4>Resumen_Sprints!$E$9,G$4<=Resumen_Sprints!$E$9+Resumen_Sprints!$D$9),INDEX('Sprint N°4'!$C$7:$P$7,G$4-Resumen_Sprints!$E$9),0)} -> 0 | H25: {=IF(AND(H$4>Resumen_Sprints!$E$9,H$4<=Resumen_Sprints!$E$9+Resumen_Sprints!$D$9),INDEX('Sprint N°4'!$C$7:$P$7,H$4-Resumen_Sprints!$E$9),0)} -> 0 | I25: {=IF(AND(I$4>Resumen_Sprints!$E$9,I$4<=Resumen_Sprints!$E$9+Resumen_Sprints!$D$9),INDEX('Sprint N°4'!$C$7:$P$7,I$4-Resumen_Sprints!$E$9),0)} -> 0 | J25: {=IF(AND(J$4>Resumen_Sprints!$E$9,J$4<=Resumen_Sprints!$E$9+Resumen_Sprints!$D$9),INDEX('Sprint N°4'!$C$7:$P$7,J$4-Resumen_Sprints!$E$9),0)} -> 0 | ... CT25: {=IF(AND(CT$4>Resumen_Sprints!$E$9,CT$4<=Resumen_Sprints!$E$9+Resumen_Sprints!$D$9),INDEX('Sprint N°4'!$C$7:$P$7,CT$4-Resumen_Sprints!$E$9),0)} -> 0 | CU25: =SUM(C25:CT25) -> 38
A26: ='Sprint N°4'!A8 -> Ajuste a Presupuesto Máximo del Usuario | B26: ='Sprint N°4'!B8 -> 36 | C26: {=IF(AND(C$4>Resumen_Sprints!$E$9,C$4<=Resumen_Sprints!$E$9+Resumen_Sprints!$D$9),INDEX('Sprint N°4'!$C$8:$P$8,C$4-Resumen_Sprints!$E$9),0)} -> 0 | D26: {=IF(AND(D$4>Resumen_Sprints!$E$9,D$4<=Resumen_Sprints!$E$9+Resumen_Sprints!$D$9),INDEX('Sprint N°4'!$C$8:$P$8,D$4-Resumen_Sprints!$E$9),0)} -> 0 | E26: {=IF(AND(E$4>Resumen_Sprints!$E$9,E$4<=Resumen_Sprints!$E$9+Resumen_Sprints!$D$9),INDEX('Sprint N°4'!$C$8:$P$8,E$4-Resumen_Sprints!$E$9),0)} -> 0 | F26: {=IF(AND(F$4>Resumen_Sprints!$E$9,F$4<=Resumen_Sprints!$E$9+Resumen_Sprints!$D$9),INDEX('Sprint N°4'!$C$8:$P$8,F$4-Resumen_Sprints!$E$9),0)} -> 0 | G26: {=IF(AND(G$4>Resumen_Sprints!$E$9,G$4<=Resumen_Sprints!$E$9+Resumen_Sprints!$D$9),INDEX('Sprint N°4'!$C$8:$P$8,G$4-Resumen_Sprints!$E$9),0)} -> 0 | H26: {=IF(AND(H$4>Resumen_Sprints!$E$9,H$4<=Resumen_Sprints!$E$9+Resumen_Sprints!$D$9),INDEX('Sprint N°4'!$C$8:$P$8,H$4-Resumen_Sprints!$E$9),0)} -> 0 | I26: {=IF(AND(I$4>Resumen_Sprints!$E$9,I$4<=Resumen_Sprints!$E$9+Resumen_Sprints!$D$9),INDEX('Sprint N°4'!$C$8:$P$8,I$4-Resumen_Sprints!$E$9),0)} -> 0 | J26: {=IF(AND(J$4>Resumen_Sprints!$E$9,J$4<=Resumen_Sprints!$E$9+Resumen_Sprints!$D$9),INDEX('Sprint N°4'!$C$8:$P$8,J$4-Resumen_Sprints!$E$9),0)} -> 0 | ... CT26: {=IF(AND(CT$4>Resumen_Sprints!$E$9,CT$4<=Resumen_Sprints!$E$9+Resumen_Sprints!$D$9),INDEX('Sprint N°4'!$C$8:$P$8,CT$4-Resumen_Sprints!$E$9),0)} -> 0 | CU26: =SUM(C26:CT26) -> 36
A27: ='Sprint N°4'!A9 -> Integración del Motor con el Catálogo de Materiales | B27: ='Sprint N°4'!B9 -> 15 | C27: {=IF(AND(C$4>Resumen_Sprints!$E$9,C$4<=Resumen_Sprints!$E$9+Resumen_Sprints!$D$9),INDEX('Sprint N°4'!$C$9:$P$9,C$4-Resumen_Sprints!$E$9),0)} -> 0 | D27: {=IF(AND(D$4>Resumen_Sprints!$E$9,D$4<=Resumen_Sprints!$E$9+Resumen_Sprints!$D$9),INDEX('Sprint N°4'!$C$9:$P$9,D$4-Resumen_Sprints!$E$9),0)} -> 0 | E27: {=IF(AND(E$4>Resumen_Sprints!$E$9,E$4<=Resumen_Sprints!$E$9+Resumen_Sprints!$D$9),INDEX('Sprint N°4'!$C$9:$P$9,E$4-Resumen_Sprints!$E$9),0)} -> 0 | F27: {=IF(AND(F$4>Resumen_Sprints!$E$9,F$4<=Resumen_Sprints!$E$9+Resumen_Sprints!$D$9),INDEX('Sprint N°4'!$C$9:$P$9,F$4-Resumen_Sprints!$E$9),0)} -> 0 | G27: {=IF(AND(G$4>Resumen_Sprints!$E$9,G$4<=Resumen_Sprints!$E$9+Resumen_Sprints!$D$9),INDEX('Sprint N°4'!$C$9:$P$9,G$4-Resumen_Sprints!$E$9),0)} -> 0 | H27: {=IF(AND(H$4>Resumen_Sprints!$E$9,H$4<=Resumen_Sprints!$E$9+Resumen_Sprints!$D$9),INDEX('Sprint N°4'!$C$9:$P$9,H$4-Resumen_Sprints!$E$9),0)} -> 0 | I27: {=IF(AND(I$4>Resumen_Sprints!$E$9,I$4<=Resumen_Sprints!$E$9+Resumen_Sprints!$D$9),INDEX('Sprint N°4'!$C$9:$P$9,I$4-Resumen_Sprints!$E$9),0)} -> 0 | J27: {=IF(AND(J$4>Resumen_Sprints!$E$9,J$4<=Resumen_Sprints!$E$9+Resumen_Sprints!$D$9),INDEX('Sprint N°4'!$C$9:$P$9,J$4-Resumen_Sprints!$E$9),0)} -> 0 | ... CT27: {=IF(AND(CT$4>Resumen_Sprints!$E$9,CT$4<=Resumen_Sprints!$E$9+Resumen_Sprints!$D$9),INDEX('Sprint N°4'!$C$9:$P$9,CT$4-Resumen_Sprints!$E$9),0)} -> 0 | CU27: =SUM(C27:CT27) -> 16
A28: ="Sprint N°"&Resumen_Sprints!A10&" – "&Resumen_Sprints!B10 -> Sprint N°5 – Interfaz Gráfica Interactiva | B28: =SUM(B29:B32) -> 97
A29: ='Sprint N°5'!A6 -> Coordinación del Objetivos Sprint 5 | B29: ='Sprint N°5'!B6 -> 1 | C29: {=IF(AND(C$4>Resumen_Sprints!$E$10,C$4<=Resumen_Sprints!$E$10+Resumen_Sprints!$D$10),INDEX('Sprint N°5'!$C$6:$R$6,C$4-Resumen_Sprints!$E$10),0)} -> 0 | D29: {=IF(AND(D$4>Resumen_Sprints!$E$10,D$4<=Resumen_Sprints!$E$10+Resumen_Sprints!$D$10),INDEX('Sprint N°5'!$C$6:$R$6,D$4-Resumen_Sprints!$E$10),0)} -> 0 | E29: {=IF(AND(E$4>Resumen_Sprints!$E$10,E$4<=Resumen_Sprints!$E$10+Resumen_Sprints!$D$10),INDEX('Sprint N°5'!$C$6:$R$6,E$4-Resumen_Sprints!$E$10),0)} -> 0 | F29: {=IF(AND(F$4>Resumen_Sprints!$E$10,F$4<=Resumen_Sprints!$E$10+Resumen_Sprints!$D$10),INDEX('Sprint N°5'!$C$6:$R$6,F$4-Resumen_Sprints!$E$10),0)} -> 0 | G29: {=IF(AND(G$4>Resumen_Sprints!$E$10,G$4<=Resumen_Sprints!$E$10+Resumen_Sprints!$D$10),INDEX('Sprint N°5'!$C$6:$R$6,G$4-Resumen_Sprints!$E$10),0)} -> 0 | H29: {=IF(AND(H$4>Resumen_Sprints!$E$10,H$4<=Resumen_Sprints!$E$10+Resumen_Sprints!$D$10),INDEX('Sprint N°5'!$C$6:$R$6,H$4-Resumen_Sprints!$E$10),0)} -> 0 | I29: {=IF(AND(I$4>Resumen_Sprints!$E$10,I$4<=Resumen_Sprints!$E$10+Resumen_Sprints!$D$10),INDEX('Sprint N°5'!$C$6:$R$6,I$4-Resumen_Sprints!$E$10),0)} -> 0 | J29: {=IF(AND(J$4>Resumen_Sprints!$E$10,J$4<=Resumen_Sprints!$E$10+Resumen_Sprints!$D$10),INDEX('Sprint N°5'!$C$6:$R$6,J$4-Resumen_Sprints!$E$10),0)} -> 0 | ... CT29: {=IF(AND(CT$4>Resumen_Sprints!$E$10,CT$4<=Resumen_Sprints!$E$10+Resumen_Sprints!$D$10),INDEX('Sprint N°5'!$C$6:$R$6,CT$4-Resumen_Sprints!$E$10),0)} -> 0 | CU29: =SUM(C29:CT29) -> 1
A30: ='Sprint N°5'!A7 -> Interfaz Principal y Formulario de Presupuesto | B30: ='Sprint N°5'!B7 -> 24 | C30: {=IF(AND(C$4>Resumen_Sprints!$E$10,C$4<=Resumen_Sprints!$E$10+Resumen_Sprints!$D$10),INDEX('Sprint N°5'!$C$7:$R$7,C$4-Resumen_Sprints!$E$10),0)} -> 0 | D30: {=IF(AND(D$4>Resumen_Sprints!$E$10,D$4<=Resumen_Sprints!$E$10+Resumen_Sprints!$D$10),INDEX('Sprint N°5'!$C$7:$R$7,D$4-Resumen_Sprints!$E$10),0)} -> 0 | E30: {=IF(AND(E$4>Resumen_Sprints!$E$10,E$4<=Resumen_Sprints!$E$10+Resumen_Sprints!$D$10),INDEX('Sprint N°5'!$C$7:$R$7,E$4-Resumen_Sprints!$E$10),0)} -> 0 | F30: {=IF(AND(F$4>Resumen_Sprints!$E$10,F$4<=Resumen_Sprints!$E$10+Resumen_Sprints!$D$10),INDEX('Sprint N°5'!$C$7:$R$7,F$4-Resumen_Sprints!$E$10),0)} -> 0 | G30: {=IF(AND(G$4>Resumen_Sprints!$E$10,G$4<=Resumen_Sprints!$E$10+Resumen_Sprints!$D$10),INDEX('Sprint N°5'!$C$7:$R$7,G$4-Resumen_Sprints!$E$10),0)} -> 0 | H30: {=IF(AND(H$4>Resumen_Sprints!$E$10,H$4<=Resumen_Sprints!$E$10+Resumen_Sprints!$D$10),INDEX('Sprint N°5'!$C$7:$R$7,H$4-Resumen_Sprints!$E$10),0)} -> 0 | I30: {=IF(AND(I$4>Resumen_Sprints!$E$10,I$4<=Resumen_Sprints!$E$10+Resumen_Sprints!$D$10),INDEX('Sprint N°5'!$C$7:$R$7,I$4-Resumen_Sprints!$E$10),0)} -> 0 | J30: {=IF(AND(J$4>Resumen_Sprints!$E$10,J$4<=Resumen_Sprints!$E$10+Resumen_Sprints!$D$10),INDEX('Sprint N°5'!$C$7:$R$7,J$4-Resumen_Sprints!$E$10),0)} -> 0 | ... CT30: {=IF(AND(CT$4>Resumen_Sprints!$E$10,CT$4<=Resumen_Sprints!$E$10+Resumen_Sprints!$D$10),INDEX('Sprint N°5'!$C$7:$R$7,CT$4-Resumen_Sprints!$E$10),0)} -> 0 | CU30: =SUM(C30:CT30) -> 24
A31: ='Sprint N°5'!A8 -> Editor Interactivo de Diseño del Hogar | B31: ='Sprint N°5'!B8 -> 49 | C31: {=IF(AND(C$4>Resumen_Sprints!$E$10,C$4<=Resumen_Sprints!$E$10+Resumen_Sprints!$D$10),INDEX('Sprint N°5'!$C$8:$R$8,C$4-Resumen_Sprints!$E$10),0)} -> 0 | D31: {=IF(AND(D$4>Resumen_Sprints!$E$10,D$4<=Resumen_Sprints!$E$10+Resumen_Sprints!$D$10),INDEX('Sprint N°5'!$C$8:$R$8,D$4-Resumen_Sprints!$E$10),0)} -> 0 | E31: {=IF(AND(E$4>Resumen_Sprints!$E$10,E$4<=Resumen_Sprints!$E$10+Resumen_Sprints!$D$10),INDEX('Sprint N°5'!$C$8:$R$8,E$4-Resumen_Sprints!$E$10),0)} -> 0 | F31: {=IF(AND(F$4>Resumen_Sprints!$E$10,F$4<=Resumen_Sprints!$E$10+Resumen_Sprints!$D$10),INDEX('Sprint N°5'!$C$8:$R$8,F$4-Resumen_Sprints!$E$10),0)} -> 0 | G31: {=IF(AND(G$4>Resumen_Sprints!$E$10,G$4<=Resumen_Sprints!$E$10+Resumen_Sprints!$D$10),INDEX('Sprint N°5'!$C$8:$R$8,G$4-Resumen_Sprints!$E$10),0)} -> 0 | H31: {=IF(AND(H$4>Resumen_Sprints!$E$10,H$4<=Resumen_Sprints!$E$10+Resumen_Sprints!$D$10),INDEX('Sprint N°5'!$C$8:$R$8,H$4-Resumen_Sprints!$E$10),0)} -> 0 | I31: {=IF(AND(I$4>Resumen_Sprints!$E$10,I$4<=Resumen_Sprints!$E$10+Resumen_Sprints!$D$10),INDEX('Sprint N°5'!$C$8:$R$8,I$4-Resumen_Sprints!$E$10),0)} -> 0 | J31: {=IF(AND(J$4>Resumen_Sprints!$E$10,J$4<=Resumen_Sprints!$E$10+Resumen_Sprints!$D$10),INDEX('Sprint N°5'!$C$8:$R$8,J$4-Resumen_Sprints!$E$10),0)} -> 0 | ... CT31: {=IF(AND(CT$4>Resumen_Sprints!$E$10,CT$4<=Resumen_Sprints!$E$10+Resumen_Sprints!$D$10),INDEX('Sprint N°5'!$C$8:$R$8,CT$4-Resumen_Sprints!$E$10),0)} -> 0 | CU31: =SUM(C31:CT31) -> 48
A32: ='Sprint N°5'!A9 -> Visualización de Resultados en Tiempo Real | B32: ='Sprint N°5'!B9 -> 23 | C32: {=IF(AND(C$4>Resumen_Sprints!$E$10,C$4<=Resumen_Sprints!$E$10+Resumen_Sprints!$D$10),INDEX('Sprint N°5'!$C$9:$R$9,C$4-Resumen_Sprints!$E$10),0)} -> 0 | D32: {=IF(AND(D$4>Resumen_Sprints!$E$10,D$4<=Resumen_Sprints!$E$10+Resumen_Sprints!$D$10),INDEX('Sprint N°5'!$C$9:$R$9,D$4-Resumen_Sprints!$E$10),0)} -> 0 | E32: {=IF(AND(E$4>Resumen_Sprints!$E$10,E$4<=Resumen_Sprints!$E$10+Resumen_Sprints!$D$10),INDEX('Sprint N°5'!$C$9:$R$9,E$4-Resumen_Sprints!$E$10),0)} -> 0 | F32: {=IF(AND(F$4>Resumen_Sprints!$E$10,F$4<=Resumen_Sprints!$E$10+Resumen_Sprints!$D$10),INDEX('Sprint N°5'!$C$9:$R$9,F$4-Resumen_Sprints!$E$10),0)} -> 0 | G32: {=IF(AND(G$4>Resumen_Sprints!$E$10,G$4<=Resumen_Sprints!$E$10+Resumen_Sprints!$D$10),INDEX('Sprint N°5'!$C$9:$R$9,G$4-Resumen_Sprints!$E$10),0)} -> 0 | H32: {=IF(AND(H$4>Resumen_Sprints!$E$10,H$4<=Resumen_Sprints!$E$10+Resumen_Sprints!$D$10),INDEX('Sprint N°5'!$C$9:$R$9,H$4-Resumen_Sprints!$E$10),0)} -> 0 | I32: {=IF(AND(I$4>Resumen_Sprints!$E$10,I$4<=Resumen_Sprints!$E$10+Resumen_Sprints!$D$10),INDEX('Sprint N°5'!$C$9:$R$9,I$4-Resumen_Sprints!$E$10),0)} -> 0 | J32: {=IF(AND(J$4>Resumen_Sprints!$E$10,J$4<=Resumen_Sprints!$E$10+Resumen_Sprints!$D$10),INDEX('Sprint N°5'!$C$9:$R$9,J$4-Resumen_Sprints!$E$10),0)} -> 0 | ... CT32: {=IF(AND(CT$4>Resumen_Sprints!$E$10,CT$4<=Resumen_Sprints!$E$10+Resumen_Sprints!$D$10),INDEX('Sprint N°5'!$C$9:$R$9,CT$4-Resumen_Sprints!$E$10),0)} -> 0 | CU32: =SUM(C32:CT32) -> 24
A33: ="Sprint N°"&Resumen_Sprints!A11&" – "&Resumen_Sprints!B11 -> Sprint N°6 – Proyección Monetaria, Integración y Ceremonias Scrum | B33: =SUM(B34:B38) -> 135
A34: ='Sprint N°6'!A6 -> Coordinación del componente | B34: ='Sprint N°6'!B6 -> 2 | C34: {=IF(AND(C$4>Resumen_Sprints!$E$11,C$4<=Resumen_Sprints!$E$11+Resumen_Sprints!$D$11),INDEX('Sprint N°6'!$C$6:$N$6,C$4-Resumen_Sprints!$E$11),0)} -> 0 | D34: {=IF(AND(D$4>Resumen_Sprints!$E$11,D$4<=Resumen_Sprints!$E$11+Resumen_Sprints!$D$11),INDEX('Sprint N°6'!$C$6:$N$6,D$4-Resumen_Sprints!$E$11),0)} -> 0 | E34: {=IF(AND(E$4>Resumen_Sprints!$E$11,E$4<=Resumen_Sprints!$E$11+Resumen_Sprints!$D$11),INDEX('Sprint N°6'!$C$6:$N$6,E$4-Resumen_Sprints!$E$11),0)} -> 0 | F34: {=IF(AND(F$4>Resumen_Sprints!$E$11,F$4<=Resumen_Sprints!$E$11+Resumen_Sprints!$D$11),INDEX('Sprint N°6'!$C$6:$N$6,F$4-Resumen_Sprints!$E$11),0)} -> 0 | G34: {=IF(AND(G$4>Resumen_Sprints!$E$11,G$4<=Resumen_Sprints!$E$11+Resumen_Sprints!$D$11),INDEX('Sprint N°6'!$C$6:$N$6,G$4-Resumen_Sprints!$E$11),0)} -> 0 | H34: {=IF(AND(H$4>Resumen_Sprints!$E$11,H$4<=Resumen_Sprints!$E$11+Resumen_Sprints!$D$11),INDEX('Sprint N°6'!$C$6:$N$6,H$4-Resumen_Sprints!$E$11),0)} -> 0 | I34: {=IF(AND(I$4>Resumen_Sprints!$E$11,I$4<=Resumen_Sprints!$E$11+Resumen_Sprints!$D$11),INDEX('Sprint N°6'!$C$6:$N$6,I$4-Resumen_Sprints!$E$11),0)} -> 0 | J34: {=IF(AND(J$4>Resumen_Sprints!$E$11,J$4<=Resumen_Sprints!$E$11+Resumen_Sprints!$D$11),INDEX('Sprint N°6'!$C$6:$N$6,J$4-Resumen_Sprints!$E$11),0)} -> 0 | ... CT34: {=IF(AND(CT$4>Resumen_Sprints!$E$11,CT$4<=Resumen_Sprints!$E$11+Resumen_Sprints!$D$11),INDEX('Sprint N°6'!$C$6:$N$6,CT$4-Resumen_Sprints!$E$11),0)} -> 0 | CU34: =SUM(C34:CT34) -> 1
A35: ='Sprint N°6'!A7 -> Generación de Proyección Monetaria del Hogar | B35: ='Sprint N°6'!B7 -> 27 | C35: {=IF(AND(C$4>Resumen_Sprints!$E$11,C$4<=Resumen_Sprints!$E$11+Resumen_Sprints!$D$11),INDEX('Sprint N°6'!$C$7:$N$7,C$4-Resumen_Sprints!$E$11),0)} -> 0 | D35: {=IF(AND(D$4>Resumen_Sprints!$E$11,D$4<=Resumen_Sprints!$E$11+Resumen_Sprints!$D$11),INDEX('Sprint N°6'!$C$7:$N$7,D$4-Resumen_Sprints!$E$11),0)} -> 0 | E35: {=IF(AND(E$4>Resumen_Sprints!$E$11,E$4<=Resumen_Sprints!$E$11+Resumen_Sprints!$D$11),INDEX('Sprint N°6'!$C$7:$N$7,E$4-Resumen_Sprints!$E$11),0)} -> 0 | F35: {=IF(AND(F$4>Resumen_Sprints!$E$11,F$4<=Resumen_Sprints!$E$11+Resumen_Sprints!$D$11),INDEX('Sprint N°6'!$C$7:$N$7,F$4-Resumen_Sprints!$E$11),0)} -> 0 | G35: {=IF(AND(G$4>Resumen_Sprints!$E$11,G$4<=Resumen_Sprints!$E$11+Resumen_Sprints!$D$11),INDEX('Sprint N°6'!$C$7:$N$7,G$4-Resumen_Sprints!$E$11),0)} -> 0 | H35: {=IF(AND(H$4>Resumen_Sprints!$E$11,H$4<=Resumen_Sprints!$E$11+Resumen_Sprints!$D$11),INDEX('Sprint N°6'!$C$7:$N$7,H$4-Resumen_Sprints!$E$11),0)} -> 0 | I35: {=IF(AND(I$4>Resumen_Sprints!$E$11,I$4<=Resumen_Sprints!$E$11+Resumen_Sprints!$D$11),INDEX('Sprint N°6'!$C$7:$N$7,I$4-Resumen_Sprints!$E$11),0)} -> 0 | J35: {=IF(AND(J$4>Resumen_Sprints!$E$11,J$4<=Resumen_Sprints!$E$11+Resumen_Sprints!$D$11),INDEX('Sprint N°6'!$C$7:$N$7,J$4-Resumen_Sprints!$E$11),0)} -> 0 | ... CT35: {=IF(AND(CT$4>Resumen_Sprints!$E$11,CT$4<=Resumen_Sprints!$E$11+Resumen_Sprints!$D$11),INDEX('Sprint N°6'!$C$7:$N$7,CT$4-Resumen_Sprints!$E$11),0)} -> 0 | CU35: =SUM(C35:CT35) -> 23
A36: ='Sprint N°6'!A8 -> Resumen y Exportación de Cotización | B36: ='Sprint N°6'!B8 -> 15 | C36: {=IF(AND(C$4>Resumen_Sprints!$E$11,C$4<=Resumen_Sprints!$E$11+Resumen_Sprints!$D$11),INDEX('Sprint N°6'!$C$8:$N$8,C$4-Resumen_Sprints!$E$11),0)} -> 0 | D36: {=IF(AND(D$4>Resumen_Sprints!$E$11,D$4<=Resumen_Sprints!$E$11+Resumen_Sprints!$D$11),INDEX('Sprint N°6'!$C$8:$N$8,D$4-Resumen_Sprints!$E$11),0)} -> 0 | E36: {=IF(AND(E$4>Resumen_Sprints!$E$11,E$4<=Resumen_Sprints!$E$11+Resumen_Sprints!$D$11),INDEX('Sprint N°6'!$C$8:$N$8,E$4-Resumen_Sprints!$E$11),0)} -> 0 | F36: {=IF(AND(F$4>Resumen_Sprints!$E$11,F$4<=Resumen_Sprints!$E$11+Resumen_Sprints!$D$11),INDEX('Sprint N°6'!$C$8:$N$8,F$4-Resumen_Sprints!$E$11),0)} -> 0 | G36: {=IF(AND(G$4>Resumen_Sprints!$E$11,G$4<=Resumen_Sprints!$E$11+Resumen_Sprints!$D$11),INDEX('Sprint N°6'!$C$8:$N$8,G$4-Resumen_Sprints!$E$11),0)} -> 0 | H36: {=IF(AND(H$4>Resumen_Sprints!$E$11,H$4<=Resumen_Sprints!$E$11+Resumen_Sprints!$D$11),INDEX('Sprint N°6'!$C$8:$N$8,H$4-Resumen_Sprints!$E$11),0)} -> 0 | I36: {=IF(AND(I$4>Resumen_Sprints!$E$11,I$4<=Resumen_Sprints!$E$11+Resumen_Sprints!$D$11),INDEX('Sprint N°6'!$C$8:$N$8,I$4-Resumen_Sprints!$E$11),0)} -> 0 | J36: {=IF(AND(J$4>Resumen_Sprints!$E$11,J$4<=Resumen_Sprints!$E$11+Resumen_Sprints!$D$11),INDEX('Sprint N°6'!$C$8:$N$8,J$4-Resumen_Sprints!$E$11),0)} -> 0 | ... CT36: {=IF(AND(CT$4>Resumen_Sprints!$E$11,CT$4<=Resumen_Sprints!$E$11+Resumen_Sprints!$D$11),INDEX('Sprint N°6'!$C$8:$N$8,CT$4-Resumen_Sprints!$E$11),0)} -> 0 | CU36: =SUM(C36:CT36) -> 13
A37: ='Sprint N°6'!A9 -> Integración del Sistema | B37: ='Sprint N°6'!B9 -> 30 | C37: {=IF(AND(C$4>Resumen_Sprints!$E$11,C$4<=Resumen_Sprints!$E$11+Resumen_Sprints!$D$11),INDEX('Sprint N°6'!$C$9:$N$9,C$4-Resumen_Sprints!$E$11),0)} -> 0 | D37: {=IF(AND(D$4>Resumen_Sprints!$E$11,D$4<=Resumen_Sprints!$E$11+Resumen_Sprints!$D$11),INDEX('Sprint N°6'!$C$9:$N$9,D$4-Resumen_Sprints!$E$11),0)} -> 0 | E37: {=IF(AND(E$4>Resumen_Sprints!$E$11,E$4<=Resumen_Sprints!$E$11+Resumen_Sprints!$D$11),INDEX('Sprint N°6'!$C$9:$N$9,E$4-Resumen_Sprints!$E$11),0)} -> 0 | F37: {=IF(AND(F$4>Resumen_Sprints!$E$11,F$4<=Resumen_Sprints!$E$11+Resumen_Sprints!$D$11),INDEX('Sprint N°6'!$C$9:$N$9,F$4-Resumen_Sprints!$E$11),0)} -> 0 | G37: {=IF(AND(G$4>Resumen_Sprints!$E$11,G$4<=Resumen_Sprints!$E$11+Resumen_Sprints!$D$11),INDEX('Sprint N°6'!$C$9:$N$9,G$4-Resumen_Sprints!$E$11),0)} -> 0 | H37: {=IF(AND(H$4>Resumen_Sprints!$E$11,H$4<=Resumen_Sprints!$E$11+Resumen_Sprints!$D$11),INDEX('Sprint N°6'!$C$9:$N$9,H$4-Resumen_Sprints!$E$11),0)} -> 0 | I37: {=IF(AND(I$4>Resumen_Sprints!$E$11,I$4<=Resumen_Sprints!$E$11+Resumen_Sprints!$D$11),INDEX('Sprint N°6'!$C$9:$N$9,I$4-Resumen_Sprints!$E$11),0)} -> 0 | J37: {=IF(AND(J$4>Resumen_Sprints!$E$11,J$4<=Resumen_Sprints!$E$11+Resumen_Sprints!$D$11),INDEX('Sprint N°6'!$C$9:$N$9,J$4-Resumen_Sprints!$E$11),0)} -> 0 | ... CT37: {=IF(AND(CT$4>Resumen_Sprints!$E$11,CT$4<=Resumen_Sprints!$E$11+Resumen_Sprints!$D$11),INDEX('Sprint N°6'!$C$9:$N$9,CT$4-Resumen_Sprints!$E$11),0)} -> 0 | CU37: =SUM(C37:CT37) -> 38
A38: ='Sprint N°6'!A10 -> Ceremonias Scrum (Planning, Review, Retrospectiva; en paralelo) | B38: ='Sprint N°6'!B10 -> 61 | C38: {=IF(AND(C$4>Resumen_Sprints!$E$11,C$4<=Resumen_Sprints!$E$11+Resumen_Sprints!$D$11),INDEX('Sprint N°6'!$C$10:$N$10,C$4-Resumen_Sprints!$E$11),0)} -> 0 | D38: {=IF(AND(D$4>Resumen_Sprints!$E$11,D$4<=Resumen_Sprints!$E$11+Resumen_Sprints!$D$11),INDEX('Sprint N°6'!$C$10:$N$10,D$4-Resumen_Sprints!$E$11),0)} -> 0 | E38: {=IF(AND(E$4>Resumen_Sprints!$E$11,E$4<=Resumen_Sprints!$E$11+Resumen_Sprints!$D$11),INDEX('Sprint N°6'!$C$10:$N$10,E$4-Resumen_Sprints!$E$11),0)} -> 0 | F38: {=IF(AND(F$4>Resumen_Sprints!$E$11,F$4<=Resumen_Sprints!$E$11+Resumen_Sprints!$D$11),INDEX('Sprint N°6'!$C$10:$N$10,F$4-Resumen_Sprints!$E$11),0)} -> 0 | G38: {=IF(AND(G$4>Resumen_Sprints!$E$11,G$4<=Resumen_Sprints!$E$11+Resumen_Sprints!$D$11),INDEX('Sprint N°6'!$C$10:$N$10,G$4-Resumen_Sprints!$E$11),0)} -> 0 | H38: {=IF(AND(H$4>Resumen_Sprints!$E$11,H$4<=Resumen_Sprints!$E$11+Resumen_Sprints!$D$11),INDEX('Sprint N°6'!$C$10:$N$10,H$4-Resumen_Sprints!$E$11),0)} -> 0 | I38: {=IF(AND(I$4>Resumen_Sprints!$E$11,I$4<=Resumen_Sprints!$E$11+Resumen_Sprints!$D$11),INDEX('Sprint N°6'!$C$10:$N$10,I$4-Resumen_Sprints!$E$11),0)} -> 0 | J38: {=IF(AND(J$4>Resumen_Sprints!$E$11,J$4<=Resumen_Sprints!$E$11+Resumen_Sprints!$D$11),INDEX('Sprint N°6'!$C$10:$N$10,J$4-Resumen_Sprints!$E$11),0)} -> 0 | ... CT38: {=IF(AND(CT$4>Resumen_Sprints!$E$11,CT$4<=Resumen_Sprints!$E$11+Resumen_Sprints!$D$11),INDEX('Sprint N°6'!$C$10:$N$10,CT$4-Resumen_Sprints!$E$11),0)} -> 0 | CU38: =SUM(C38:CT38) -> 60
A39: ="Sprint N°"&Resumen_Sprints!A12&" – "&Resumen_Sprints!B12 -> Sprint N°7 – Pruebas y Corrección de Defectos | B39: =SUM(B40:B44) -> 114
